Workbook
Name ACTIVE_REPS: '⚙ Lists'!$M$3:$M$6
Name ALL_BEDS: '⚙ Lists'!$Y$3:$Y$28
Name CLOSERS: '⚙ Lists'!$S$3:$S$5
Name DO_NOT_READMIT: '⚙ Lists'!$N$4:$N$8
Name FACILITY: '⚙ Lists'!$D$3:$D$6
Name HP_ROOMS: '⚙ Lists'!$T$3:$T$16
Name HPE_ROOMS: '⚙ Lists'!$U$3:$U$14
Name INS_TYPE: '⚙ Lists'!$F$3:$F$11
Name INSURANCE_OK: '⚙ Lists'!$E$3:$E$16
Name LOC: '⚙ Lists'!$C$3:$C$8
Name MONTHS: '⚙ Lists'!$W$3:$W$10
Name NON_CONTRACTED: '⚙ Lists'!$L$3:$L$17
Name PLAN_LOS: '⚙ Lists'!$V$3:$V$11
Name REF_CAT: '⚙ Lists'!$G$3:$G$11
Name REPS: '⚙ Lists'!$A$3:$A$8
Name STATUS: '⚙ Lists'!$B$3:$B$8
Name TEMP: '⚙ Lists'!$H$3:$H$5
Name YESNO: '⚙ Lists'!$I$3:$I$4

Sheet 📊 Dashboard
A1: 🏥 HARMONY PLACE — ADMISSIONS DASHBOARD
A2: ="Updated: "&TEXT(NOW(),"ddd M/D h:MM AM/PM") -> Updated: Wed 6/17 12:48 PM | E2: ="Total: "&(COUNTIF('🛏 HP Bed Board'!B10:B23,"Occupied")+(COUNTIF('🛏 HPE Bed Board'!B11:B16,"Occupied")+COUNTIF('🛏 HPE Bed Board'!B18:B23,"Occupied")))&"/26 · "&(COUNTIF('🛏 HP Bed Board'!B10:B23,"Open")+(COUNTIF('🛏 HPE Bed Board'!B11:B16,"Open")+COUNTIF('🛏 HPE Bed Board'!B18:B23,"Open")))&" open" -> Total: 20/26 · 5 open
A4: 🛏 COMMAND CENTER — LIVE CENSUS & FLOW
A5: HP Census | B5: HPE Census | C5: Total | D5: Open Beds | E5: Reserved | F5: Adm MTD | G5: Conv % | H5: Proj 7d
A6: =COUNTIF('🛏 HP Bed Board'!B10:B23,"Occupied")&"/14" -> 11/14 | B6: =(COUNTIF('🛏 HPE Bed Board'!B11:B16,"Occupied")+COUNTIF('🛏 HPE Bed Board'!B18:B23,"Occupied"))&"/12" -> 9/12 | C6: =(COUNTIF('🛏 HP Bed Board'!B10:B23,"Occupied")+(COUNTIF('🛏 HPE Bed Board'!B11:B16,"Occupied")+COUNTIF('🛏 HPE Bed Board'!B18:B23,"Occupied")))&"/26" -> 20/26 | D6: =COUNTIF('🛏 HP Bed Board'!B10:B23,"Open")+(COUNTIF('🛏 HPE Bed Board'!B11:B16,"Open")+COUNTIF('🛏 HPE Bed Board'!B18:B23,"Open")) -> 5 | E6: =COUNTIF('🛏 HP Bed Board'!B10:B23,"Reserved")+(COUNTIF('🛏 HPE Bed Board'!B11:B16,"Reserved")+COUNTIF('🛏 HPE Bed Board'!B18:B23,"Reserved")) -> 1 | F6: =$C$74 -> 13 | G6: =$D$74 -> 1 | H6: =$G$74 -> 17
A8: =" ⚠ DISCHARGE WATCH — Next 7 days ("&SUM('⚙ Census Engine'!$AB$10:$AB$35)&" discharging)" -> ⚠ DISCHARGE WATCH — Next 7 days (4 discharging)
A9: Client | B9: Fac | C9: Room | D9: Admit | E9: Day # | F9: DC Date | G9: To DC | H9: Rep | I9: LOC | J9: Financial
A10: =IFERROR(INDEX('⚙ Census Engine'!$AD$10:$AD$35,MATCH(ROW()-9,'⚙ Census Engine'!$AC$10:$AC$35,0)),"") -> Rhonda Baim | B10: =IFERROR(INDEX('⚙ Census Engine'!$AE$10:$AE$35,MATCH(ROW()-9,'⚙ Census Engine'!$AC$10:$AC$35,0)),"") -> HPE | C10: =IFERROR(INDEX('⚙ Census Engine'!$AF$10:$AF$35,MATCH(ROW()-9,'⚙ Census Engine'!$AC$10:$AC$35,0)),"") -> H1-2A | D10: =IFERROR(INDEX('⚙ Census Engine'!$AG$10:$AG$35,MATCH(ROW()-9,'⚙ Census Engine'!$AC$10:$AC$35,0)),"") -> 5/24 | E10: =IFERROR(INDEX('⚙ Census Engine'!$AH$10:$AH$35,MATCH(ROW()-9,'⚙ Census Engine'!$AC$10:$AC$35,0)),"") -> 24 | F10: =IFERROR(INDEX('⚙ Census Engine'!$AI$10:$AI$35,MATCH(ROW()-9,'⚙ Census Engine'!$AC$10:$AC$35,0)),"") -> 6/23 | G10: =IFERROR(INDEX('⚙ Census Engine'!$AJ$10:$AJ$35,MATCH(ROW()-9,'⚙ Census Engine'!$AC$10:$AC$35,0)),"") -> 6d | H10: =IFERROR(INDEX('⚙ Census Engine'!$AK$10:$AK$35,MATCH(ROW()-9,'⚙ Census Engine'!$AC$10:$AC$35,0)),"") -> Nelson | I10: =IFERROR(INDEX('⚙ Census Engine'!$AL$10:$AL$35,MATCH(ROW()-9,'⚙ Census Engine'!$AC$10:$AC$35,0)),"") -> DTX | J10: =IFERROR(INDEX('⚙ Census Engine'!$AM$10:$AM$35,MATCH(ROW()-9,'⚙ Census Engine'!$AC$10:$AC$35,0)),"") -> Anthem BC
A11: =IFERROR(INDEX('⚙ Census Engine'!$AD$10:$AD$35,MATCH(ROW()-9,'⚙ Census Engine'!$AC$10:$AC$35,0)),"") -> Darian Loehner | B11: =IFERROR(INDEX('⚙ Census Engine'!$AE$10:$AE$35,MATCH(ROW()-9,'⚙ Census Engine'!$AC$10:$AC$35,0)),"") -> HP | C11: =IFERROR(INDEX('⚙ Census Engine'!$AF$10:$AF$35,MATCH(ROW()-9,'⚙ Census Engine'!$AC$10:$AC$35,0)),"") -> M2-B | D11: =IFERROR(INDEX('⚙ Census Engine'!$AG$10:$AG$35,MATCH(ROW()-9,'⚙ Census Engine'!$AC$10:$AC$35,0)),"") -> 6/10 | E11: =IFERROR(INDEX('⚙ Census Engine'!$AH$10:$AH$35,MATCH(ROW()-9,'⚙ Census Engine'!$AC$10:$AC$35,0)),"") -> 7 | F11: =IFERROR(INDEX('⚙ Census Engine'!$AI$10:$AI$35,MATCH(ROW()-9,'⚙ Census Engine'!$AC$10:$AC$35,0)),"") -> 6/20 | G11: =IFERROR(INDEX('⚙ Census Engine'!$AJ$10:$AJ$35,MATCH(ROW()-9,'⚙ Census Engine'!$AC$10:$AC$35,0)),"") -> 3d | H11: =IFERROR(INDEX('⚙ Census Engine'!$AK$10:$AK$35,MATCH(ROW()-9,'⚙ Census Engine'!$AC$10:$AC$35,0)),"") -> Amy | I11: =IFERROR(INDEX('⚙ Census Engine'!$AL$10:$AL$35,MATCH(ROW()-9,'⚙ Census Engine'!$AC$10:$AC$35,0)),"") -> DTX | J11: =IFERROR(INDEX('⚙ Census Engine'!$AM$10:$AM$35,MATCH(ROW()-9,'⚙ Census Engine'!$AC$10:$AC$35,0)),"") -> Aetna
A12: =IFERROR(INDEX('⚙ Census Engine'!$AD$10:$AD$35,MATCH(ROW()-9,'⚙ Census Engine'!$AC$10:$AC$35,0)),"") -> Monica Gamboa | B12: =IFERROR(INDEX('⚙ Census Engine'!$AE$10:$AE$35,MATCH(ROW()-9,'⚙ Census Engine'!$AC$10:$AC$35,0)),"") -> HP | C12: =IFERROR(INDEX('⚙ Census Engine'!$AF$10:$AF$35,MATCH(ROW()-9,'⚙ Census Engine'!$AC$10:$AC$35,0)),"") -> M3-B | D12: =IFERROR(INDEX('⚙ Census Engine'!$AG$10:$AG$35,MATCH(ROW()-9,'⚙ Census Engine'!$AC$10:$AC$35,0)),"") -> 6/11 | E12: =IFERROR(INDEX('⚙ Census Engine'!$AH$10:$AH$35,MATCH(ROW()-9,'⚙ Census Engine'!$AC$10:$AC$35,0)),"") -> 6 | F12: =IFERROR(INDEX('⚙ Census Engine'!$AI$10:$AI$35,MATCH(ROW()-9,'⚙ Census Engine'!$AC$10:$AC$35,0)),"") -> 6/21 | G12: =IFERROR(INDEX('⚙ Census Engine'!$AJ$10:$AJ$35,MATCH(ROW()-9,'⚙ Census Engine'!$AC$10:$AC$35,0)),"") -> 4d | H12: =IFERROR(INDEX('⚙ Census Engine'!$AK$10:$AK$35,MATCH(ROW()-9,'⚙ Census Engine'!$AC$10:$AC$35,0)),"") -> Amy | I12: =IFERROR(INDEX('⚙ Census Engine'!$AL$10:$AL$35,MATCH(ROW()-9,'⚙ Census Engine'!$AC$10:$AC$35,0)),"") -> DTX/RTC | J12: =IFERROR(INDEX('⚙ Census Engine'!$AM$10:$AM$35,MATCH(ROW()-9,'⚙ Census Engine'!$AC$10:$AC$35,0)),"") -> Molina CA
A13: =IFERROR(INDEX('⚙ Census Engine'!$AD$10:$AD$35,MATCH(ROW()-9,'⚙ Census Engine'!$AC$10:$AC$35,0)),"") -> Allisa Leuvrey | B13: =IFERROR(INDEX('⚙ Census Engine'!$AE$10:$AE$35,MATCH(ROW()-9,'⚙ Census Engine'!$AC$10:$AC$35,0)),"") -> HPE | C13: =IFERROR(INDEX('⚙ Census Engine'!$AF$10:$AF$35,MATCH(ROW()-9,'⚙ Census Engine'!$AC$10:$AC$35,0)),"") -> H1-1A | D13: =IFERROR(INDEX('⚙ Census Engine'!$AG$10:$AG$35,MATCH(ROW()-9,'⚙ Census Engine'!$AC$10:$AC$35,0)),"") -> 6/12 | E13: =IFERROR(INDEX('⚙ Census Engine'!$AH$10:$AH$35,MATCH(ROW()-9,'⚙ Census Engine'!$AC$10:$AC$35,0)),"") -> 5 | F13: =IFERROR(INDEX('⚙ Census Engine'!$AI$10:$AI$35,MATCH(ROW()-9,'⚙ Census Engine'!$AC$10:$AC$35,0)),"") -> 6/19 | G13: =IFERROR(INDEX('⚙ Census Engine'!$AJ$10:$AJ$35,MATCH(ROW()-9,'⚙ Census Engine'!$AC$10:$AC$35,0)),"") -> 2d | H13: =IFERROR(INDEX('⚙ Census Engine'!$AK$10:$AK$35,MATCH(ROW()-9,'⚙ Census Engine'!$AC$10:$AC$35,0)),"") -> Amy | I13: =IFERROR(INDEX('⚙ Census Engine'!$AL$10:$AL$35,MATCH(ROW()-9,'⚙ Census Engine'!$AC$10:$AC$35,0)),"") -> DTX | J13: =IFERROR(INDEX('⚙ Census Engine'!$AM$10:$AM$35,MATCH(ROW()-9,'⚙ Census Engine'!$AC$10:$AC$35,0)),"") -> Blue Shield CA
A14: =IFERROR(INDEX('⚙ Census Engine'!$AD$10:$AD$35,MATCH(ROW()-9,'⚙ Census Engine'!$AC$10:$AC$35,0)),"") | B14: =IFERROR(INDEX('⚙ Census Engine'!$AE$10:$AE$35,MATCH(ROW()-9,'⚙ Census Engine'!$AC$10:$AC$35,0)),"") | C14: =IFERROR(INDEX('⚙ Census Engine'!$AF$10:$AF$35,MATCH(ROW()-9,'⚙ Census Engine'!$AC$10:$AC$35,0)),"") | D14: =IFERROR(INDEX('⚙ Census Engine'!$AG$10:$AG$35,MATCH(ROW()-9,'⚙ Census Engine'!$AC$10:$AC$35,0)),"") | E14: =IFERROR(INDEX('⚙ Census Engine'!$AH$10:$AH$35,MATCH(ROW()-9,'⚙ Census Engine'!$AC$10:$AC$35,0)),"") | F14: =IFERROR(INDEX('⚙ Census Engine'!$AI$10:$AI$35,MATCH(ROW()-9,'⚙ Census Engine'!$AC$10:$AC$35,0)),"") | G14: =IFERROR(INDEX('⚙ Census Engine'!$AJ$10:$AJ$35,MATCH(ROW()-9,'⚙ Census Engine'!$AC$10:$AC$35,0)),"") | H14: =IFERROR(INDEX('⚙ Census Engine'!$AK$10:$AK$35,MATCH(ROW()-9,'⚙ Census Engine'!$AC$10:$AC$35,0)),"") | I14: =IFERROR(INDEX('⚙ Census Engine'!$AL$10:$AL$35,MATCH(ROW()-9,'⚙ Census Engine'!$AC$10:$AC$35,0)),"") | J14: =IFERROR(INDEX('⚙ Census Engine'!$AM$10:$AM$35,MATCH(ROW()-9,'⚙ Census Engine'!$AC$10:$AC$35,0)),"")
A15: =IFERROR(INDEX('⚙ Census Engine'!$AD$10:$AD$35,MATCH(ROW()-9,'⚙ Census Engine'!$AC$10:$AC$35,0)),"") | B15: =IFERROR(INDEX('⚙ Census Engine'!$AE$10:$AE$35,MATCH(ROW()-9,'⚙ Census Engine'!$AC$10:$AC$35,0)),"") | C15: =IFERROR(INDEX('⚙ Census Engine'!$AF$10:$AF$35,MATCH(ROW()-9,'⚙ Census Engine'!$AC$10:$AC$35,0)),"") | D15: =IFERROR(INDEX('⚙ Census Engine'!$AG$10:$AG$35,MATCH(ROW()-9,'⚙ Census Engine'!$AC$10:$AC$35,0)),"") | E15: =IFERROR(INDEX('⚙ Census Engine'!$AH$10:$AH$35,MATCH(ROW()-9,'⚙ Census Engine'!$AC$10:$AC$35,0)),"") | F15: =IFERROR(INDEX('⚙ Census Engine'!$AI$10:$AI$35,MATCH(ROW()-9,'⚙ Census Engine'!$AC$10:$AC$35,0)),"") | G15: =IFERROR(INDEX('⚙ Census Engine'!$AJ$10:$AJ$35,MATCH(ROW()-9,'⚙ Census Engine'!$AC$10:$AC$35,0)),"") | H15: =IFERROR(INDEX('⚙ Census Engine'!$AK$10:$AK$35,MATCH(ROW()-9,'⚙ Census Engine'!$AC$10:$AC$35,0)),"") | I15: =IFERROR(INDEX('⚙ Census Engine'!$AL$10:$AL$35,MATCH(ROW()-9,'⚙ Census Engine'!$AC$10:$AC$35,0)),"") | J15: =IFERROR(INDEX('⚙ Census Engine'!$AM$10:$AM$35,MATCH(ROW()-9,'⚙ Census Engine'!$AC$10:$AC$35,0)),"")
A16: =IFERROR(INDEX('⚙ Census Engine'!$AD$10:$AD$35,MATCH(ROW()-9,'⚙ Census Engine'!$AC$10:$AC$35,0)),"") | B16: =IFERROR(INDEX('⚙ Census Engine'!$AE$10:$AE$35,MATCH(ROW()-9,'⚙ Census Engine'!$AC$10:$AC$35,0)),"") | C16: =IFERROR(INDEX('⚙ Census Engine'!$AF$10:$AF$35,MATCH(ROW()-9,'⚙ Census Engine'!$AC$10:$AC$35,0)),"") | D16: =IFERROR(INDEX('⚙ Census Engine'!$AG$10:$AG$35,MATCH(ROW()-9,'⚙ Census Engine'!$AC$10:$AC$35,0)),"") | E16: =IFERROR(INDEX('⚙ Census Engine'!$AH$10:$AH$35,MATCH(ROW()-9,'⚙ Census Engine'!$AC$10:$AC$35,0)),"") | F16: =IFERROR(INDEX('⚙ Census Engine'!$AI$10:$AI$35,MATCH(ROW()-9,'⚙ Census Engine'!$AC$10:$AC$35,0)),"") | G16: =IFERROR(INDEX('⚙ Census Engine'!$AJ$10:$AJ$35,MATCH(ROW()-9,'⚙ Census Engine'!$AC$10:$AC$35,0)),"") | H16: =IFERROR(INDEX('⚙ Census Engine'!$AK$10:$AK$35,MATCH(ROW()-9,'⚙ Census Engine'!$AC$10:$AC$35,0)),"") | I16: =IFERROR(INDEX('⚙ Census Engine'!$AL$10:$AL$35,MATCH(ROW()-9,'⚙ Census Engine'!$AC$10:$AC$35,0)),"") | J16: =IFERROR(INDEX('⚙ Census Engine'!$AM$10:$AM$35,MATCH(ROW()-9,'⚙ Census Engine'!$AC$10:$AC$35,0)),"")
A17: =IFERROR(INDEX('⚙ Census Engine'!$AD$10:$AD$35,MATCH(ROW()-9,'⚙ Census Engine'!$AC$10:$AC$35,0)),"") | B17: =IFERROR(INDEX('⚙ Census Engine'!$AE$10:$AE$35,MATCH(ROW()-9,'⚙ Census Engine'!$AC$10:$AC$35,0)),"") | C17: =IFERROR(INDEX('⚙ Census Engine'!$AF$10:$AF$35,MATCH(ROW()-9,'⚙ Census Engine'!$AC$10:$AC$35,0)),"") | D17: =IFERROR(INDEX('⚙ Census Engine'!$AG$10:$AG$35,MATCH(ROW()-9,'⚙ Census Engine'!$AC$10:$AC$35,0)),"") | E17: =IFERROR(INDEX('⚙ Census Engine'!$AH$10:$AH$35,MATCH(ROW()-9,'⚙ Census Engine'!$AC$10:$AC$35,0)),"") | F17: =IFERROR(INDEX('⚙ Census Engine'!$AI$10:$AI$35,MATCH(ROW()-9,'⚙ Census Engine'!$AC$10:$AC$35,0)),"") | G17: =IFERROR(INDEX('⚙ Census Engine'!$AJ$10:$AJ$35,MATCH(ROW()-9,'⚙ Census Engine'!$AC$10:$AC$35,0)),"") | H17: =IFERROR(INDEX('⚙ Census Engine'!$AK$10:$AK$35,MATCH(ROW()-9,'⚙ Census Engine'!$AC$10:$AC$35,0)),"") | I17: =IFERROR(INDEX('⚙ Census Engine'!$AL$10:$AL$35,MATCH(ROW()-9,'⚙ Census Engine'!$AC$10:$AC$35,0)),"") | J17: =IFERROR(INDEX('⚙ Census Engine'!$AM$10:$AM$35,MATCH(ROW()-9,'⚙ Census Engine'!$AC$10:$AC$35,0)),"")
A18: =IFERROR(INDEX('⚙ Census Engine'!$AD$10:$AD$35,MATCH(ROW()-9,'⚙ Census Engine'!$AC$10:$AC$35,0)),"") | B18: =IFERROR(INDEX('⚙ Census Engine'!$AE$10:$AE$35,MATCH(ROW()-9,'⚙ Census Engine'!$AC$10:$AC$35,0)),"") | C18: =IFERROR(INDEX('⚙ Census Engine'!$AF$10:$AF$35,MATCH(ROW()-9,'⚙ Census Engine'!$AC$10:$AC$35,0)),"") | D18: =IFERROR(INDEX('⚙ Census Engine'!$AG$10:$AG$35,MATCH(ROW()-9,'⚙ Census Engine'!$AC$10:$AC$35,0)),"") | E18: =IFERROR(INDEX('⚙ Census Engine'!$AH$10:$AH$35,MATCH(ROW()-9,'⚙ Census Engine'!$AC$10:$AC$35,0)),"") | F18: =IFERROR(INDEX('⚙ Census Engine'!$AI$10:$AI$35,MATCH(ROW()-9,'⚙ Census Engine'!$AC$10:$AC$35,0)),"") | G18: =IFERROR(INDEX('⚙ Census Engine'!$AJ$10:$AJ$35,MATCH(ROW()-9,'⚙ Census Engine'!$AC$10:$AC$35,0)),"") | H18: =IFERROR(INDEX('⚙ Census Engine'!$AK$10:$AK$35,MATCH(ROW()-9,'⚙ Census Engine'!$AC$10:$AC$35,0)),"") | I18: =IFERROR(INDEX('⚙ Census Engine'!$AL$10:$AL$35,MATCH(ROW()-9,'⚙ Census Engine'!$AC$10:$AC$35,0)),"") | J18: =IFERROR(INDEX('⚙ Census Engine'!$AM$10:$AM$35,MATCH(ROW()-9,'⚙ Census Engine'!$AC$10:$AC$35,0)),"")
A19: =IFERROR(INDEX('⚙ Census Engine'!$AD$10:$AD$35,MATCH(ROW()-9,'⚙ Census Engine'!$AC$10:$AC$35,0)),"") | B19: =IFERROR(INDEX('⚙ Census Engine'!$AE$10:$AE$35,MATCH(ROW()-9,'⚙ Census Engine'!$AC$10:$AC$35,0)),"") | C19: =IFERROR(INDEX('⚙ Census Engine'!$AF$10:$AF$35,MATCH(ROW()-9,'⚙ Census Engine'!$AC$10:$AC$35,0)),"") | D19: =IFERROR(INDEX('⚙ Census Engine'!$AG$10:$AG$35,MATCH(ROW()-9,'⚙ Census Engine'!$AC$10:$AC$35,0)),"") | E19: =IFERROR(INDEX('⚙ Census Engine'!$AH$10:$AH$35,MATCH(ROW()-9,'⚙ Census Engine'!$AC$10:$AC$35,0)),"") | F19: =IFERROR(INDEX('⚙ Census Engine'!$AI$10:$AI$35,MATCH(ROW()-9,'⚙ Census Engine'!$AC$10:$AC$35,0)),"") | G19: =IFERROR(INDEX('⚙ Census Engine'!$AJ$10:$AJ$35,MATCH(ROW()-9,'⚙ Census Engine'!$AC$10:$AC$35,0)),"") | H19: =IFERROR(INDEX('⚙ Census Engine'!$AK$10:$AK$35,MATCH(ROW()-9,'⚙ Census Engine'!$AC$10:$AC$35,0)),"") | I19: =IFERROR(INDEX('⚙ Census Engine'!$AL$10:$AL$35,MATCH(ROW()-9,'⚙ Census Engine'!$AC$10:$AC$35,0)),"") | J19: =IFERROR(INDEX('⚙ Census Engine'!$AM$10:$AM$35,MATCH(ROW()-9,'⚙ Census Engine'!$AC$10:$AC$35,0)),"")
A20: =IFERROR(INDEX('⚙ Census Engine'!$AD$10:$AD$35,MATCH(ROW()-9,'⚙ Census Engine'!$AC$10:$AC$35,0)),"") | B20: =IFERROR(INDEX('⚙ Census Engine'!$AE$10:$AE$35,MATCH(ROW()-9,'⚙ Census Engine'!$AC$10:$AC$35,0)),"") | C20: =IFERROR(INDEX('⚙ Census Engine'!$AF$10:$AF$35,MATCH(ROW()-9,'⚙ Census Engine'!$AC$10:$AC$35,0)),"") | D20: =IFERROR(INDEX('⚙ Census Engine'!$AG$10:$AG$35,MATCH(ROW()-9,'⚙ Census Engine'!$AC$10:$AC$35,0)),"") | E20: =IFERROR(INDEX('⚙ Census Engine'!$AH$10:$AH$35,MATCH(ROW()-9,'⚙ Census Engine'!$AC$10:$AC$35,0)),"") | F20: =IFERROR(INDEX('⚙ Census Engine'!$AI$10:$AI$35,MATCH(ROW()-9,'⚙ Census Engine'!$AC$10:$AC$35,0)),"") | G20: =IFERROR(INDEX('⚙ Census Engine'!$AJ$10:$AJ$35,MATCH(ROW()-9,'⚙ Census Engine'!$AC$10:$AC$35,0)),"") | H20: =IFERROR(INDEX('⚙ Census Engine'!$AK$10:$AK$35,MATCH(ROW()-9,'⚙ Census Engine'!$AC$10:$AC$35,0)),"") | I20: =IFERROR(INDEX('⚙ Census Engine'!$AL$10:$AL$35,MATCH(ROW()-9,'⚙ Census Engine'!$AC$10:$AC$35,0)),"") | J20: =IFERROR(INDEX('⚙ Census Engine'!$AM$10:$AM$35,MATCH(ROW()-9,'⚙ Census Engine'!$AC$10:$AC$35,0)),"")
A21: =IFERROR(INDEX('⚙ Census Engine'!$AD$10:$AD$35,MATCH(ROW()-9,'⚙ Census Engine'!$AC$10:$AC$35,0)),"") | B21: =IFERROR(INDEX('⚙ Census Engine'!$AE$10:$AE$35,MATCH(ROW()-9,'⚙ Census Engine'!$AC$10:$AC$35,0)),"") | C21: =IFERROR(INDEX('⚙ Census Engine'!$AF$10:$AF$35,MATCH(ROW()-9,'⚙ Census Engine'!$AC$10:$AC$35,0)),"") | D21: =IFERROR(INDEX('⚙ Census Engine'!$AG$10:$AG$35,MATCH(ROW()-9,'⚙ Census Engine'!$AC$10:$AC$35,0)),"") | E21: =IFERROR(INDEX('⚙ Census Engine'!$AH$10:$AH$35,MATCH(ROW()-9,'⚙ Census Engine'!$AC$10:$AC$35,0)),"") | F21: =IFERROR(INDEX('⚙ Census Engine'!$AI$10:$AI$35,MATCH(ROW()-9,'⚙ Census Engine'!$AC$10:$AC$35,0)),"") | G21: =IFERROR(INDEX('⚙ Census Engine'!$AJ$10:$AJ$35,MATCH(ROW()-9,'⚙ Census Engine'!$AC$10:$AC$35,0)),"") | H21: =IFERROR(INDEX('⚙ Census Engine'!$AK$10:$AK$35,MATCH(ROW()-9,'⚙ Census Engine'!$AC$10:$AC$35,0)),"") | I21: =IFERROR(INDEX('⚙ Census Engine'!$AL$10:$AL$35,MATCH(ROW()-9,'⚙ Census Engine'!$AC$10:$AC$35,0)),"") | J21: =IFERROR(INDEX('⚙ Census Engine'!$AM$10:$AM$35,MATCH(ROW()-9,'⚙ Census Engine'!$AC$10:$AC$35,0)),"")
A23: 📥 SCHEDULED INTAKES — auto-pulled from Pipeline (Status = Scheduled)
A24: Client | B24: Rep | C24: Fac | D24: LOC | E24: Insurance | F24: Intake | G24: VOB
A25: =IFERROR(INDEX('🔥 Pipeline'!$C:$C,MATCH(ROW()-24,'⚙ Pipeline Engine'!$AB:$AB,0)),"") -> Tara Shinde | B25: =IFERROR(INDEX('🔥 Pipeline'!$B:$B,MATCH(ROW()-24,'⚙ Pipeline Engine'!$AB:$AB,0)),"") -> Amy | C25: =IFERROR(INDEX('🔥 Pipeline'!$F:$F,MATCH(ROW()-24,'⚙ Pipeline Engine'!$AB:$AB,0)),"") -> HPE | D25: =IFERROR(INDEX('🔥 Pipeline'!$E:$E,MATCH(ROW()-24,'⚙ Pipeline Engine'!$AB:$AB,0)),"") -> DTX/RTC | E25: =IFERROR(INDEX('🔥 Pipeline'!$I:$I,MATCH(ROW()-24,'⚙ Pipeline Engine'!$AB:$AB,0)),"") -> BCBS IL | F25: =IFERROR(INDEX('🔥 Pipeline'!$H:$H,MATCH(ROW()-24,'⚙ Pipeline Engine'!$AB:$AB,0)),"") -> 46192 | G25: =IFERROR(INDEX('🔥 Pipeline'!$G:$G,MATCH(ROW()-24,'⚙ Pipeline Engine'!$AB:$AB,0)),"") -> ✓
A26: =IFERROR(INDEX('🔥 Pipeline'!$C:$C,MATCH(ROW()-24,'⚙ Pipeline Engine'!$AB:$AB,0)),"") | B26: =IFERROR(INDEX('🔥 Pipeline'!$B:$B,MATCH(ROW()-24,'⚙ Pipeline Engine'!$AB:$AB,0)),"") | C26: =IFERROR(INDEX('🔥 Pipeline'!$F:$F,MATCH(ROW()-24,'⚙ Pipeline Engine'!$AB:$AB,0)),"") | D26: =IFERROR(INDEX('🔥 Pipeline'!$E:$E,MATCH(ROW()-24,'⚙ Pipeline Engine'!$AB:$AB,0)),"") | E26: =IFERROR(INDEX('🔥 Pipeline'!$I:$I,MATCH(ROW()-24,'⚙ Pipeline Engine'!$AB:$AB,0)),"") | F26: =IFERROR(INDEX('🔥 Pipeline'!$H:$H,MATCH(ROW()-24,'⚙ Pipeline Engine'!$AB:$AB,0)),"") | G26: =IFERROR(INDEX('🔥 Pipeline'!$G:$G,MATCH(ROW()-24,'⚙ Pipeline Engine'!$AB:$AB,0)),"")
A27: =IFERROR(INDEX('🔥 Pipeline'!$C:$C,MATCH(ROW()-24,'⚙ Pipeline Engine'!$AB:$AB,0)),"") | B27: =IFERROR(INDEX('🔥 Pipeline'!$B:$B,MATCH(ROW()-24,'⚙ Pipeline Engine'!$AB:$AB,0)),"") | C27: =IFERROR(INDEX('🔥 Pipeline'!$F:$F,MATCH(ROW()-24,'⚙ Pipeline Engine'!$AB:$AB,0)),"") | D27: =IFERROR(INDEX('🔥 Pipeline'!$E:$E,MATCH(ROW()-24,'⚙ Pipeline Engine'!$AB:$AB,0)),"") | E27: =IFERROR(INDEX('🔥 Pipeline'!$I:$I,MATCH(ROW()-24,'⚙ Pipeline Engine'!$AB:$AB,0)),"") | F27: =IFERROR(INDEX('🔥 Pipeline'!$H:$H,MATCH(ROW()-24,'⚙ Pipeline Engine'!$AB:$AB,0)),"") | G27: =IFERROR(INDEX('🔥 Pipeline'!$G:$G,MATCH(ROW()-24,'⚙ Pipeline Engine'!$AB:$AB,0)),"")
A28: =IFERROR(INDEX('🔥 Pipeline'!$C:$C,MATCH(ROW()-24,'⚙ Pipeline Engine'!$AB:$AB,0)),"") | B28: =IFERROR(INDEX('🔥 Pipeline'!$B:$B,MATCH(ROW()-24,'⚙ Pipeline Engine'!$AB:$AB,0)),"") | C28: =IFERROR(INDEX('🔥 Pipeline'!$F:$F,MATCH(ROW()-24,'⚙ Pipeline Engine'!$AB:$AB,0)),"") | D28: =IFERROR(INDEX('🔥 Pipeline'!$E:$E,MATCH(ROW()-24,'⚙ Pipeline Engine'!$AB:$AB,0)),"") | E28: =IFERROR(INDEX('🔥 Pipeline'!$I:$I,MATCH(ROW()-24,'⚙ Pipeline Engine'!$AB:$AB,0)),"") | F28: =IFERROR(INDEX('🔥 Pipeline'!$H:$H,MATCH(ROW()-24,'⚙ Pipeline Engine'!$AB:$AB,0)),"") | G28: =IFERROR(INDEX('🔥 Pipeline'!$G:$G,MATCH(ROW()-24,'⚙ Pipeline Engine'!$AB:$AB,0)),"")
A29: =IFERROR(INDEX('🔥 Pipeline'!$C:$C,MATCH(ROW()-24,'⚙ Pipeline Engine'!$AB:$AB,0)),"") | B29: =IFERROR(INDEX('🔥 Pipeline'!$B:$B,MATCH(ROW()-24,'⚙ Pipeline Engine'!$AB:$AB,0)),"") | C29: =IFERROR(INDEX('🔥 Pipeline'!$F:$F,MATCH(ROW()-24,'⚙ Pipeline Engine'!$AB:$AB,0)),"") | D29: =IFERROR(INDEX('🔥 Pipeline'!$E:$E,MATCH(ROW()-24,'⚙ Pipeline Engine'!$AB:$AB,0)),"") | E29: =IFERROR(INDEX('🔥 Pipeline'!$I:$I,MATCH(ROW()-24,'⚙ Pipeline Engine'!$AB:$AB,0)),"") | F29: =IFERROR(INDEX('🔥 Pipeline'!$H:$H,MATCH(ROW()-24,'⚙ Pipeline Engine'!$AB:$AB,0)),"") | G29: =IFERROR(INDEX('🔥 Pipeline'!$G:$G,MATCH(ROW()-24,'⚙ Pipeline Engine'!$AB:$AB,0)),"")
A30: =IFERROR(INDEX('🔥 Pipeline'!$C:$C,MATCH(ROW()-24,'⚙ Pipeline Engine'!$AB:$AB,0)),"") | B30: =IFERROR(INDEX('🔥 Pipeline'!$B:$B,MATCH(ROW()-24,'⚙ Pipeline Engine'!$AB:$AB,0)),"") | C30: =IFERROR(INDEX('🔥 Pipeline'!$F:$F,MATCH(ROW()-24,'⚙ Pipeline Engine'!$AB:$AB,0)),"") | D30: =IFERROR(INDEX('🔥 Pipeline'!$E:$E,MATCH(ROW()-24,'⚙ Pipeline Engine'!$AB:$AB,0)),"") | E30: =IFERROR(INDEX('🔥 Pipeline'!$I:$I,MATCH(ROW()-24,'⚙ Pipeline Engine'!$AB:$AB,0)),"") | F30: =IFERROR(INDEX('🔥 Pipeline'!$H:$H,MATCH(ROW()-24,'⚙ Pipeline Engine'!$AB:$AB,0)),"") | G30: =IFERROR(INDEX('🔥 Pipeline'!$G:$G,MATCH(ROW()-24,'⚙ Pipeline Engine'!$AB:$AB,0)),"")
A31: =IFERROR(INDEX('🔥 Pipeline'!$C:$C,MATCH(ROW()-24,'⚙ Pipeline Engine'!$AB:$AB,0)),"") | B31: =IFERROR(INDEX('🔥 Pipeline'!$B:$B,MATCH(ROW()-24,'⚙ Pipeline Engine'!$AB:$AB,0)),"") | C31: =IFERROR(INDEX('🔥 Pipeline'!$F:$F,MATCH(ROW()-24,'⚙ Pipeline Engine'!$AB:$AB,0)),"") | D31: =IFERROR(INDEX('🔥 Pipeline'!$E:$E,MATCH(ROW()-24,'⚙ Pipeline Engine'!$AB:$AB,0)),"") | E31: =IFERROR(INDEX('🔥 Pipeline'!$I:$I,MATCH(ROW()-24,'⚙ Pipeline Engine'!$AB:$AB,0)),"") | F31: =IFERROR(INDEX('🔥 Pipeline'!$H:$H,MATCH(ROW()-24,'⚙ Pipeline Engine'!$AB:$AB,0)),"") | G31: =IFERROR(INDEX('🔥 Pipeline'!$G:$G,MATCH(ROW()-24,'⚙ Pipeline Engine'!$AB:$AB,0)),"")
A33: =" 📈 ADMISSIONS BY REP — "&'⚙ Lists'!$AB$10&" (current month · auto-rolls)" -> 📈 ADMISSIONS BY REP — 📋 Jun 2026 (current month · auto-rolls)
A34: Rep | B34: Admits | C34: Pace | D34: Met-CT | E34: Met-CT %
A35: Amy (weekdays) | B35: =SUMIFS('⚙ Production Engine'!$C:$C,'⚙ Production Engine'!$A:$A,'⚙ Lists'!$AB$10,'⚙ Production Engine'!$B:$B,"Amy") -> 5 | C35: =REPT("█",B35)&REPT("░",MAX(0,15-B35)) -> █████░░░░░░░░░░ | D35: =SUMIFS('⚙ Production Engine'!$D:$D,'⚙ Production Engine'!$A:$A,'⚙ Lists'!$AB$10,'⚙ Production Engine'!$B:$B,"Amy") -> 5 | E35: =IFERROR(IF(B35=0,"—",D35/B35),"—") -> 1
A36: Nelson (weekdays) | B36: =SUMIFS('⚙ Production Engine'!$C:$C,'⚙ Production Engine'!$A:$A,'⚙ Lists'!$AB$10,'⚙ Production Engine'!$B:$B,"Nelson") -> 2 | C36: =REPT("█",B36)&REPT("░",MAX(0,15-B36)) -> ██░░░░░░░░░░░░░ | D36: =SUMIFS('⚙ Production Engine'!$D:$D,'⚙ Production Engine'!$A:$A,'⚙ Lists'!$AB$10,'⚙ Production Engine'!$B:$B,"Nelson") -> 2 | E36: =IFERROR(IF(B36=0,"—",D36/B36),"—") -> 1
A37: Matthew (weekends) | B37: =SUMIFS('⚙ Production Engine'!$C:$C,'⚙ Production Engine'!$A:$A,'⚙ Lists'!$AB$10,'⚙ Production Engine'!$B:$B,"Matthew") -> 4 | C37: =REPT("█",B37)&REPT("░",MAX(0,15-B37)) -> ████░░░░░░░░░░░ | D37: =SUMIFS('⚙ Production Engine'!$D:$D,'⚙ Production Engine'!$A:$A,'⚙ Lists'!$AB$10,'⚙ Production Engine'!$B:$B,"Matthew") -> 1 | E37: =IFERROR(IF(B37=0,"—",D37/B37),"—") -> 0.25
A38: Ahbra (evenings) | B38: =SUMIFS('⚙ Production Engine'!$C:$C,'⚙ Production Engine'!$A:$A,'⚙ Lists'!$AB$10,'⚙ Production Engine'!$B:$B,"Ahbra") -> 2 | C38: =REPT("█",B38)&REPT("░",MAX(0,15-B38)) -> ██░░░░░░░░░░░░░ | D38: =SUMIFS('⚙ Production Engine'!$D:$D,'⚙ Production Engine'!$A:$A,'⚙ Lists'!$AB$10,'⚙ Production Engine'!$B:$B,"Ahbra") -> 1 | E38: =IFERROR(IF(B38=0,"—",D38/B38),"—") -> 0.5
A39: Amos (on leave) | B39: =SUMIFS('⚙ Production Engine'!$C:$C,'⚙ Production Engine'!$A:$A,'⚙ Lists'!$AB$10,'⚙ Production Engine'!$B:$B,"Amos") -> 0 | C39: =REPT("█",B39)&REPT("░",MAX(0,15-B39)) -> ░░░░░░░░░░░░░░░ | D39: =SUMIFS('⚙ Production Engine'!$D:$D,'⚙ Production Engine'!$A:$A,'⚙ Lists'!$AB$10,'⚙ Production Engine'!$B:$B,"Amos") -> 0 | E39: =IFERROR(IF(B39=0,"—",D39/B39),"—") -> —
A40: TEAM | B40: =SUM(B35:B39) -> 13 | D40: =SUM(D35:D39) -> 9 | E40: =IFERROR(D40/B40,"—") -> 0.69230769
A42: 📊 OCCUPANCY & OPEN-BED REVENUE AT RISK
A43: House | B43: Occupied | C43: Capacity | D43: Open
A44: Harmony Place (HP) | B44: =COUNTIF('🛏 HP Bed Board'!B10:B23,"Occupied") -> 11 | C44: 14 | D44: =COUNTIF('🛏 HP Bed Board'!B10:B23,"Open") -> 3 | E44: =REPT("█",ROUND(B44/C44*20,0))&REPT("░",20-ROUND(B44/C44*20,0))&" "&TEXT(B44/C44,"0%") -> ████████████████░░░░ 79%
A45: Harmony Place East (HPE) | B45: =(COUNTIF('🛏 HPE Bed Board'!B11:B16,"Occupied")+COUNTIF('🛏 HPE Bed Board'!B18:B23,"Occupied")) -> 9 | C45: 12 | D45: =(COUNTIF('🛏 HPE Bed Board'!B11:B16,"Open")+COUNTIF('🛏 HPE Bed Board'!B18:B23,"Open")) -> 2 | E45: =REPT("█",ROUND(B45/C45*20,0))&REPT("░",20-ROUND(B45/C45*20,0))&" "&TEXT(B45/C45,"0%") -> ███████████████░░░░░ 75%
...

Sheet 🖨 Meeting
A1: 🏥 HARMONY PLACE — ADMISSIONS MEETING
A2: ="As of "&TEXT(NOW(),"dddd, mmmm d, yyyy") -> As of Wednesday, June 17, 2026
A4: 🛏 CENSUS SNAPSHOT
A5: HP Census | B5: HPE Census | C5: Total | D5: Open Beds | E5: Reserved | F5: Adm MTD | G5: Conv % | H5: Proj 7d
A6: ='📊 Dashboard'!A6 -> 11/14 | B6: ='📊 Dashboard'!B6 -> 9/12 | C6: ='📊 Dashboard'!C6 -> 20/26 | D6: ='📊 Dashboard'!D6 -> 5 | E6: ='📊 Dashboard'!E6 -> 1 | F6: ='📊 Dashboard'!F6 -> 13 | G6: ='📊 Dashboard'!G6 -> 1 | H6: ='📊 Dashboard'!H6 -> 17
A8: =" ⚠ DISCHARGE WATCH — NEXT 7 DAYS ("&SUM('⚙ Census Engine'!$AB$10:$AB$35)&" total)" -> ⚠ DISCHARGE WATCH — NEXT 7 DAYS (4 total)
A9: Client | B9: Fac | C9: Room | D9: Admit | E9: Day # | F9: DC Date | G9: To DC | H9: Rep | I9: LOC | J9: Financial
A10: ='📊 Dashboard'!A10 -> Rhonda Baim | B10: ='📊 Dashboard'!B10 -> HPE | C10: ='📊 Dashboard'!C10 -> H1-2A | D10: ='📊 Dashboard'!D10 -> 5/24 | E10: ='📊 Dashboard'!E10 -> 24 | F10: ='📊 Dashboard'!F10 -> 6/23 | G10: ='📊 Dashboard'!G10 -> 6d | H10: ='📊 Dashboard'!H10 -> Nelson | ... J10: ='📊 Dashboard'!J10 -> Anthem BC
A11: ='📊 Dashboard'!A11 -> Darian Loehner | B11: ='📊 Dashboard'!B11 -> HP | C11: ='📊 Dashboard'!C11 -> M2-B | D11: ='📊 Dashboard'!D11 -> 6/10 | E11: ='📊 Dashboard'!E11 -> 7 | F11: ='📊 Dashboard'!F11 -> 6/20 | G11: ='📊 Dashboard'!G11 -> 3d | H11: ='📊 Dashboard'!H11 -> Amy | ... J11: ='📊 Dashboard'!J11 -> Aetna
A12: ='📊 Dashboard'!A12 -> Monica Gamboa | B12: ='📊 Dashboard'!B12 -> HP | C12: ='📊 Dashboard'!C12 -> M3-B | D12: ='📊 Dashboard'!D12 -> 6/11 | E12: ='📊 Dashboard'!E12 -> 6 | F12: ='📊 Dashboard'!F12 -> 6/21 | G12: ='📊 Dashboard'!G12 -> 4d | H12: ='📊 Dashboard'!H12 -> Amy | ... J12: ='📊 Dashboard'!J12 -> Molina CA
A13: ='📊 Dashboard'!A13 -> Allisa Leuvrey | B13: ='📊 Dashboard'!B13 -> HPE | C13: ='📊 Dashboard'!C13 -> H1-1A | D13: ='📊 Dashboard'!D13 -> 6/12 | E13: ='📊 Dashboard'!E13 -> 5 | F13: ='📊 Dashboard'!F13 -> 6/19 | G13: ='📊 Dashboard'!G13 -> 2d | H13: ='📊 Dashboard'!H13 -> Amy | ... J13: ='📊 Dashboard'!J13 -> Blue Shield CA
A14: ='📊 Dashboard'!A14 | B14: ='📊 Dashboard'!B14 | C14: ='📊 Dashboard'!C14 | D14: ='📊 Dashboard'!D14 | E14: ='📊 Dashboard'!E14 | F14: ='📊 Dashboard'!F14 | G14: ='📊 Dashboard'!G14 | H14: ='📊 Dashboard'!H14 | ... J14: ='📊 Dashboard'!J14
A15: ='📊 Dashboard'!A15 | B15: ='📊 Dashboard'!B15 | C15: ='📊 Dashboard'!C15 | D15: ='📊 Dashboard'!D15 | E15: ='📊 Dashboard'!E15 | F15: ='📊 Dashboard'!F15 | G15: ='📊 Dashboard'!G15 | H15: ='📊 Dashboard'!H15 | ... J15: ='📊 Dashboard'!J15
A16: ='📊 Dashboard'!A16 | B16: ='📊 Dashboard'!B16 | C16: ='📊 Dashboard'!C16 | D16: ='📊 Dashboard'!D16 | E16: ='📊 Dashboard'!E16 | F16: ='📊 Dashboard'!F16 | G16: ='📊 Dashboard'!G16 | H16: ='📊 Dashboard'!H16 | ... J16: ='📊 Dashboard'!J16
A17: ='📊 Dashboard'!A17 | B17: ='📊 Dashboard'!B17 | C17: ='📊 Dashboard'!C17 | D17: ='📊 Dashboard'!D17 | E17: ='📊 Dashboard'!E17 | F17: ='📊 Dashboard'!F17 | G17: ='📊 Dashboard'!G17 | H17: ='📊 Dashboard'!H17 | ... J17: ='📊 Dashboard'!J17
A19: =" 📅 SCHEDULED INTAKES ("&COUNTIF('🔥 Pipeline'!$D$5:$D$100,"Scheduled")&" scheduled)" -> 📅 SCHEDULED INTAKES (1 scheduled)
A20: Client | B20: Rep | C20: Fac | D20: LOC | E20: Insurance | F20: Intake | G20: VOB
A21: ='📊 Dashboard'!A25 -> Tara Shinde | B21: ='📊 Dashboard'!B25 -> Amy | C21: ='📊 Dashboard'!C25 -> HPE | D21: ='📊 Dashboard'!D25 -> DTX/RTC | E21: ='📊 Dashboard'!E25 -> BCBS IL | F21: ='📊 Dashboard'!F25 -> 46192 | G21: ='📊 Dashboard'!G25 -> ✓
A22: ='📊 Dashboard'!A26 | B22: ='📊 Dashboard'!B26 | C22: ='📊 Dashboard'!C26 | D22: ='📊 Dashboard'!D26 | E22: ='📊 Dashboard'!E26 | F22: ='📊 Dashboard'!F26 | G22: ='📊 Dashboard'!G26
A23: ='📊 Dashboard'!A27 | B23: ='📊 Dashboard'!B27 | C23: ='📊 Dashboard'!C27 | D23: ='📊 Dashboard'!D27 | E23: ='📊 Dashboard'!E27 | F23: ='📊 Dashboard'!F27 | G23: ='📊 Dashboard'!G27
A24: ='📊 Dashboard'!A28 | B24: ='📊 Dashboard'!B28 | C24: ='📊 Dashboard'!C28 | D24: ='📊 Dashboard'!D28 | E24: ='📊 Dashboard'!E28 | F24: ='📊 Dashboard'!F28 | G24: ='📊 Dashboard'!G28
A25: ='📊 Dashboard'!A29 | B25: ='📊 Dashboard'!B29 | C25: ='📊 Dashboard'!C29 | D25: ='📊 Dashboard'!D29 | E25: ='📊 Dashboard'!E29 | F25: ='📊 Dashboard'!F29 | G25: ='📊 Dashboard'!G29
A27: =" 🔥 ACTIVE PIPELINE ("&(COUNTIF('🔥 Pipeline'!$D$5:$D$40,"Scheduled")+COUNTIF('🔥 Pipeline'!$D$5:$D$40,"Prospect")+COUNTIF('🔥 Pipeline'!$D$5:$D$40,"Lead")+COUNTIF('🔥 Pipeline'!$D$5:$D$40,"Hold"))&" active)" -> 🔥 ACTIVE PIPELINE (12 active)
A28: # | B28: Rep | C28: Client | D28: Status | E28: LOC | F28: Fac | G28: VOB | H28: Intake | I28: Insurance | J28: Referral
A29: =IF('🔥 Pipeline'!$C5="","",'🔥 Pipeline'!A5) -> 1 | B29: =IF('🔥 Pipeline'!$C5="","",'🔥 Pipeline'!B5) -> Amy | C29: =IF('🔥 Pipeline'!$C5="","",'🔥 Pipeline'!C5) -> Christopher Knight | D29: =IF('🔥 Pipeline'!$C5="","",'🔥 Pipeline'!D5) -> Prospect | E29: =IF('🔥 Pipeline'!$C5="","",'🔥 Pipeline'!E5) -> DTX/RTC | F29: =IF('🔥 Pipeline'!$C5="","",'🔥 Pipeline'!F5) -> HP | G29: =IF('🔥 Pipeline'!$C5="","",'🔥 Pipeline'!G5) -> ✓ | H29: =IF('🔥 Pipeline'!$C5="","",'🔥 Pipeline'!H5) -> TBD | I29: =IF('🔥 Pipeline'!$C5="","",'🔥 Pipeline'!I5) -> Anthem BC | J29: =IF('🔥 Pipeline'!$C5="","",'🔥 Pipeline'!K5) -> Web
A30: =IF('🔥 Pipeline'!$C6="","",'🔥 Pipeline'!A6) -> 2 | B30: =IF('🔥 Pipeline'!$C6="","",'🔥 Pipeline'!B6) -> Amy | C30: =IF('🔥 Pipeline'!$C6="","",'🔥 Pipeline'!C6) -> Nicolas Leuvrey | D30: =IF('🔥 Pipeline'!$C6="","",'🔥 Pipeline'!D6) -> Prospect | E30: =IF('🔥 Pipeline'!$C6="","",'🔥 Pipeline'!E6) -> DTX | F30: =IF('🔥 Pipeline'!$C6="","",'🔥 Pipeline'!F6) -> HPE | G30: =IF('🔥 Pipeline'!$C6="","",'🔥 Pipeline'!G6) -> ✓ | H30: =IF('🔥 Pipeline'!$C6="","",'🔥 Pipeline'!H6) -> TBD | I30: =IF('🔥 Pipeline'!$C6="","",'🔥 Pipeline'!I6) -> Private Pay | J30: =IF('🔥 Pipeline'!$C6="","",'🔥 Pipeline'!K6) -> Alumni
A31: =IF('🔥 Pipeline'!$C7="","",'🔥 Pipeline'!A7) -> 3 | B31: =IF('🔥 Pipeline'!$C7="","",'🔥 Pipeline'!B7) -> Amy | C31: =IF('🔥 Pipeline'!$C7="","",'🔥 Pipeline'!C7) -> Tara Shinde | D31: =IF('🔥 Pipeline'!$C7="","",'🔥 Pipeline'!D7) -> Scheduled | E31: =IF('🔥 Pipeline'!$C7="","",'🔥 Pipeline'!E7) -> DTX/RTC | F31: =IF('🔥 Pipeline'!$C7="","",'🔥 Pipeline'!F7) -> HPE | G31: =IF('🔥 Pipeline'!$C7="","",'🔥 Pipeline'!G7) -> ✓ | H31: =IF('🔥 Pipeline'!$C7="","",'🔥 Pipeline'!H7) -> 46192 | I31: =IF('🔥 Pipeline'!$C7="","",'🔥 Pipeline'!I7) -> BCBS IL | J31: =IF('🔥 Pipeline'!$C7="","",'🔥 Pipeline'!K7) -> Web
A32: =IF('🔥 Pipeline'!$C8="","",'🔥 Pipeline'!A8) -> 4 | B32: =IF('🔥 Pipeline'!$C8="","",'🔥 Pipeline'!B8) -> Amy | C32: =IF('🔥 Pipeline'!$C8="","",'🔥 Pipeline'!C8) -> Kimberly Cote | D32: =IF('🔥 Pipeline'!$C8="","",'🔥 Pipeline'!D8) -> Lead | E32: =IF('🔥 Pipeline'!$C8="","",'🔥 Pipeline'!E8) -> DTX/RTC | F32: =IF('🔥 Pipeline'!$C8="","",'🔥 Pipeline'!F8) -> HP | G32: =IF('🔥 Pipeline'!$C8="","",'🔥 Pipeline'!G8) -> ✓ | H32: =IF('🔥 Pipeline'!$C8="","",'🔥 Pipeline'!H8) -> TBD | I32: =IF('🔥 Pipeline'!$C8="","",'🔥 Pipeline'!I8) -> UMR | J32: =IF('🔥 Pipeline'!$C8="","",'🔥 Pipeline'!K8) -> Web
A33: =IF('🔥 Pipeline'!$C9="","",'🔥 Pipeline'!A9) -> 5 | B33: =IF('🔥 Pipeline'!$C9="","",'🔥 Pipeline'!B9) -> Amy | C33: =IF('🔥 Pipeline'!$C9="","",'🔥 Pipeline'!C9) -> Andrew Battley | D33: =IF('🔥 Pipeline'!$C9="","",'🔥 Pipeline'!D9) -> Lead | E33: =IF('🔥 Pipeline'!$C9="","",'🔥 Pipeline'!E9) -> DTX/RTC | F33: =IF('🔥 Pipeline'!$C9="","",'🔥 Pipeline'!F9) -> HPE | G33: =IF('🔥 Pipeline'!$C9="","",'🔥 Pipeline'!G9) -> ✓ | H33: =IF('🔥 Pipeline'!$C9="","",'🔥 Pipeline'!H9) -> TBD | I33: =IF('🔥 Pipeline'!$C9="","",'🔥 Pipeline'!I9) -> Aetna | J33: =IF('🔥 Pipeline'!$C9="","",'🔥 Pipeline'!K9) -> Web
A34: =IF('🔥 Pipeline'!$C10="","",'🔥 Pipeline'!A10) -> 6 | B34: =IF('🔥 Pipeline'!$C10="","",'🔥 Pipeline'!B10) -> Nelson | C34: =IF('🔥 Pipeline'!$C10="","",'🔥 Pipeline'!C10) -> Frederic Spieser | D34: =IF('🔥 Pipeline'!$C10="","",'🔥 Pipeline'!D10) -> Lead | E34: =IF('🔥 Pipeline'!$C10="","",'🔥 Pipeline'!E10) -> DTX/RTC | F34: =IF('🔥 Pipeline'!$C10="","",'🔥 Pipeline'!F10) -> HP | G34: =IF('🔥 Pipeline'!$C10="","",'🔥 Pipeline'!G10) -> ✓ | H34: =IF('🔥 Pipeline'!$C10="","",'🔥 Pipeline'!H10) -> TBD | I34: =IF('🔥 Pipeline'!$C10="","",'🔥 Pipeline'!I10) -> UHC | J34: =IF('🔥 Pipeline'!$C10="","",'🔥 Pipeline'!K10) -> Web
A35: =IF('🔥 Pipeline'!$C11="","",'🔥 Pipeline'!A11) -> 7 | B35: =IF('🔥 Pipeline'!$C11="","",'🔥 Pipeline'!B11) -> Nelson | C35: =IF('🔥 Pipeline'!$C11="","",'🔥 Pipeline'!C11) -> Michael Cardenas | D35: =IF('🔥 Pipeline'!$C11="","",'🔥 Pipeline'!D11) -> Prospect | E35: =IF('🔥 Pipeline'!$C11="","",'🔥 Pipeline'!E11) -> DTX/RTC | F35: =IF('🔥 Pipeline'!$C11="","",'🔥 Pipeline'!F11) -> TBD | G35: =IF('🔥 Pipeline'!$C11="","",'🔥 Pipeline'!G11) -> ✓ | H35: =IF('🔥 Pipeline'!$C11="","",'🔥 Pipeline'!H11) -> TBD | I35: =IF('🔥 Pipeline'!$C11="","",'🔥 Pipeline'!I11) -> UHC | J35: =IF('🔥 Pipeline'!$C11="","",'🔥 Pipeline'!K11) -> Web
A36: =IF('🔥 Pipeline'!$C12="","",'🔥 Pipeline'!A12) -> 8 | B36: =IF('🔥 Pipeline'!$C12="","",'🔥 Pipeline'!B12) -> Nelson | C36: =IF('🔥 Pipeline'!$C12="","",'🔥 Pipeline'!C12) -> Holly Webster | D36: =IF('🔥 Pipeline'!$C12="","",'🔥 Pipeline'!D12) -> Prospect | E36: =IF('🔥 Pipeline'!$C12="","",'🔥 Pipeline'!E12) -> DTX/RTC | F36: =IF('🔥 Pipeline'!$C12="","",'🔥 Pipeline'!F12) -> TBD | G36: =IF('🔥 Pipeline'!$C12="","",'🔥 Pipeline'!G12) -> ✓ | H36: =IF('🔥 Pipeline'!$C12="","",'🔥 Pipeline'!H12) -> 46191 | I36: =IF('🔥 Pipeline'!$C12="","",'🔥 Pipeline'!I12) -> Aetna | J36: =IF('🔥 Pipeline'!$C12="","",'🔥 Pipeline'!K12) -> Web
A37: =IF('🔥 Pipeline'!$C13="","",'🔥 Pipeline'!A13) -> 9 | B37: =IF('🔥 Pipeline'!$C13="","",'🔥 Pipeline'!B13) -> Matthew | C37: =IF('🔥 Pipeline'!$C13="","",'🔥 Pipeline'!C13) -> Samuel Lieberman | D37: =IF('🔥 Pipeline'!$C13="","",'🔥 Pipeline'!D13) -> Lead | E37: =IF('🔥 Pipeline'!$C13="","",'🔥 Pipeline'!E13) -> DTX/RTC | F37: =IF('🔥 Pipeline'!$C13="","",'🔥 Pipeline'!F13) -> TBD | G37: =IF('🔥 Pipeline'!$C13="","",'🔥 Pipeline'!G13) -> ✓ | H37: =IF('🔥 Pipeline'!$C13="","",'🔥 Pipeline'!H13) -> TBD | I37: =IF('🔥 Pipeline'!$C13="","",'🔥 Pipeline'!I13) -> Aetna | J37: =IF('🔥 Pipeline'!$C13="","",'🔥 Pipeline'!K13) -> Web
A38: =IF('🔥 Pipeline'!$C14="","",'🔥 Pipeline'!A14) | B38: =IF('🔥 Pipeline'!$C14="","",'🔥 Pipeline'!B14) | C38: =IF('🔥 Pipeline'!$C14="","",'🔥 Pipeline'!C14) | D38: =IF('🔥 Pipeline'!$C14="","",'🔥 Pipeline'!D14) | E38: =IF('🔥 Pipeline'!$C14="","",'🔥 Pipeline'!E14) | F38: =IF('🔥 Pipeline'!$C14="","",'🔥 Pipeline'!F14) | G38: =IF('🔥 Pipeline'!$C14="","",'🔥 Pipeline'!G14) | H38: =IF('🔥 Pipeline'!$C14="","",'🔥 Pipeline'!H14) | I38: =IF('🔥 Pipeline'!$C14="","",'🔥 Pipeline'!I14) | J38: =IF('🔥 Pipeline'!$C14="","",'🔥 Pipeline'!K14)
A39: =IF('🔥 Pipeline'!$C15="","",'🔥 Pipeline'!A15) | B39: =IF('🔥 Pipeline'!$C15="","",'🔥 Pipeline'!B15) | C39: =IF('🔥 Pipeline'!$C15="","",'🔥 Pipeline'!C15) | D39: =IF('🔥 Pipeline'!$C15="","",'🔥 Pipeline'!D15) | E39: =IF('🔥 Pipeline'!$C15="","",'🔥 Pipeline'!E15) | F39: =IF('🔥 Pipeline'!$C15="","",'🔥 Pipeline'!F15) | G39: =IF('🔥 Pipeline'!$C15="","",'🔥 Pipeline'!G15) | H39: =IF('🔥 Pipeline'!$C15="","",'🔥 Pipeline'!H15) | I39: =IF('🔥 Pipeline'!$C15="","",'🔥 Pipeline'!I15) | J39: =IF('🔥 Pipeline'!$C15="","",'🔥 Pipeline'!K15)
A40: =IF('🔥 Pipeline'!$C16="","",'🔥 Pipeline'!A16) -> 12 | B40: =IF('🔥 Pipeline'!$C16="","",'🔥 Pipeline'!B16) -> Ahbra | C40: =IF('🔥 Pipeline'!$C16="","",'🔥 Pipeline'!C16) -> Allison Warren | D40: =IF('🔥 Pipeline'!$C16="","",'🔥 Pipeline'!D16) -> Prospect | E40: =IF('🔥 Pipeline'!$C16="","",'🔥 Pipeline'!E16) -> DTX/RTC | F40: =IF('🔥 Pipeline'!$C16="","",'🔥 Pipeline'!F16) -> HP | G40: =IF('🔥 Pipeline'!$C16="","",'🔥 Pipeline'!G16) -> ✓ | H40: =IF('🔥 Pipeline'!$C16="","",'🔥 Pipeline'!H16) -> TBD | I40: =IF('🔥 Pipeline'!$C16="","",'🔥 Pipeline'!I16) -> UHC | J40: =IF('🔥 Pipeline'!$C16="","",'🔥 Pipeline'!K16) -> Professional Referral

Sheet 📝 Roster
A1: 📝 CENSUS ROSTER — the single place you edit
A2: Add a client and pick their CURRENT BED to place them. To move someone, just change their Current Bed — the HP / HPE boards update automatically. A bed nobody is assigned to shows Open.
A3: CLIENT NAME | B3: CURRENT BED | C3: STATUS | D3: ADMIT DATE | E3: ADMIT LOC | F3: CURRENT LOC | G3: PLAN LOS | H3: FINANCIAL | I3: REFERRAL | J3: REP | K3: CHIRO Y/N | L3: AMA RISK | M3: DC LOC | N3: DC OVERRIDE | O3: DC DATE | P3: DAYS TO DC
A4: 🏠 HP — HATTERAS (23041 / 23043) | Q4: Alumni?
B5: DTX-A | O5: =IF($A5="","",IF($N5<>"",$N5,IF(AND($D5<>"",$G5<>""),$D5+$G5,""))) | P5: =IF(O5="","",O5-TODAY()) | Q5: =IF(OR($A5="",$D5=""),"",IF((COUNTIFS('📋 May 2026'!$B$5:$B$60,$A5,'📋 May 2026'!$C$5:$C$60,"<"&$D5)+COUNTIFS('📋 Jun 2026'!$B$5:$B$60,$A5,'📋 Jun 2026'!$C$5:$C$60,"<"&$D5)+COUNTIFS('📋 Jul 2026'!$B$5:$B$60,$A5,'📋 Jul 2026'!$C$5:$C$60,"<"&$D5)+COUNTIFS('📋 Aug 2026'!$B$5:$B$60,$A5,'📋 Aug 2026'!$C$5:$C$60,"<"&$D5)+COUNTIFS('📋 Sep 2026'!$B$5:$B$60,$A5,'📋 Sep 2026'!$C$5:$C$60,"<"&$D5)+COUNTIFS('📋 Oct 2026'!$B$5:$B$60,$A5,'📋 Oct 2026'!$C$5:$C$60,"<"&$D5)+COUNTIFS('📋 Nov 2026'!$B$5:$B$60,$A5,'📋 Nov 2026'!$C$5:$C$60,"<"&$D5)+COUNTIFS('📋 Dec 2026'!$B$5:$B$60,$A5,'📋 Dec 2026'!$C$5:$C$60,"<"&$D5))+(COUNTIFS('📋 May 2026'!$B$5:$B$60,$A5,'📋 May 2026'!$AB$5:$AB$60,"Alumni")+COUNTIFS('📋 Jun 2026'!$B$5:$B$60,$A5,'📋 Jun 2026'!$AB$5:$AB$60,"Alumni")+COUNTIFS('📋 Jul 2026'!$B$5:$B$60,$A5,'📋 Jul 2026'!$AB$5:$AB$60,"Alumni")+COUNTIFS('📋 Aug 2026'!$B$5:$B$60,$A5,'📋 Aug 2026'!$AB$5:$AB$60,"Alumni")+COUNTIFS('📋 Sep 2026'!$B$5:$B$60,$A5,'📋 Sep 2026'!$AB$5:$AB$60,"Alumni")+COUNTIFS('📋 Oct 2026'!$B$5:$B$60,$A5,'📋 Oct 2026'!$AB$5:$AB$60,"Alumni")+COUNTIFS('📋 Nov 2026'!$B$5:$B$60,$A5,'📋 Nov 2026'!$AB$5:$AB$60,"Alumni")+COUNTIFS('📋 Dec 2026'!$B$5:$B$60,$A5,'📋 Dec 2026'!$AB$5:$AB$60,"Alumni"))>=1,"Alumni","New"))
B6: DTX-B | O6: =IF($A6="","",IF($N6<>"",$N6,IF(AND($D6<>"",$G6<>""),$D6+$G6,""))) | P6: =IF(O6="","",O6-TODAY()) | Q6: =IF(OR($A6="",$D6=""),"",IF((COUNTIFS('📋 May 2026'!$B$5:$B$60,$A6,'📋 May 2026'!$C$5:$C$60,"<"&$D6)+COUNTIFS('📋 Jun 2026'!$B$5:$B$60,$A6,'📋 Jun 2026'!$C$5:$C$60,"<"&$D6)+COUNTIFS('📋 Jul 2026'!$B$5:$B$60,$A6,'📋 Jul 2026'!$C$5:$C$60,"<"&$D6)+COUNTIFS('📋 Aug 2026'!$B$5:$B$60,$A6,'📋 Aug 2026'!$C$5:$C$60,"<"&$D6)+COUNTIFS('📋 Sep 2026'!$B$5:$B$60,$A6,'📋 Sep 2026'!$C$5:$C$60,"<"&$D6)+COUNTIFS('📋 Oct 2026'!$B$5:$B$60,$A6,'📋 Oct 2026'!$C$5:$C$60,"<"&$D6)+COUNTIFS('📋 Nov 2026'!$B$5:$B$60,$A6,'📋 Nov 2026'!$C$5:$C$60,"<"&$D6)+COUNTIFS('📋 Dec 2026'!$B$5:$B$60,$A6,'📋 Dec 2026'!$C$5:$C$60,"<"&$D6))+(COUNTIFS('📋 May 2026'!$B$5:$B$60,$A6,'📋 May 2026'!$AB$5:$AB$60,"Alumni")+COUNTIFS('📋 Jun 2026'!$B$5:$B$60,$A6,'📋 Jun 2026'!$AB$5:$AB$60,"Alumni")+COUNTIFS('📋 Jul 2026'!$B$5:$B$60,$A6,'📋 Jul 2026'!$AB$5:$AB$60,"Alumni")+COUNTIFS('📋 Aug 2026'!$B$5:$B$60,$A6,'📋 Aug 2026'!$AB$5:$AB$60,"Alumni")+COUNTIFS('📋 Sep 2026'!$B$5:$B$60,$A6,'📋 Sep 2026'!$AB$5:$AB$60,"Alumni")+COUNTIFS('📋 Oct 2026'!$B$5:$B$60,$A6,'📋 Oct 2026'!$AB$5:$AB$60,"Alumni")+COUNTIFS('📋 Nov 2026'!$B$5:$B$60,$A6,'📋 Nov 2026'!$AB$5:$AB$60,"Alumni")+COUNTIFS('📋 Dec 2026'!$B$5:$B$60,$A6,'📋 Dec 2026'!$AB$5:$AB$60,"Alumni"))>=1,"Alumni","New"))
A7: Kurt Guisler | B7: M1-A | C7: Occupied | D7: 46172 | E7: DTX/RTC | F7: DTX/RTC | G7: 30 | H7: Blue Shield PPO | I7: Skyline/Ahbra | J7: Amy | K7: N | N7: 46201 | O7: =IF($A7="","",IF($N7<>"",$N7,IF(AND($D7<>"",$G7<>""),$D7+$G7,""))) -> 46201 | P7: =IF(O7="","",O7-TODAY()) -> 11 | Q7: =IF(OR($A7="",$D7=""),"",IF((COUNTIFS('📋 May 2026'!$B$5:$B$60,$A7,'📋 May 2026'!$C$5:$C$60,"<"&$D7)+COUNTIFS('📋 Jun 2026'!$B$5:$B$60,$A7,'📋 Jun 2026'!$C$5:$C$60,"<"&$D7)+COUNTIFS('📋 Jul 2026'!$B$5:$B$60,$A7,'📋 Jul 2026'!$C$5:$C$60,"<"&$D7)+COUNTIFS('📋 Aug 2026'!$B$5:$B$60,$A7,'📋 Aug 2026'!$C$5:$C$60,"<"&$D7)+COUNTIFS('📋 Sep 2026'!$B$5:$B$60,$A7,'📋 Sep 2026'!$C$5:$C$60,"<"&$D7)+COUNTIFS('📋 Oct 2026'!$B$5:$B$60,$A7,'📋 Oct 2026'!$C$5:$C$60,"<"&$D7)+COUNTIFS('📋 Nov 2026'!$B$5:$B$60,$A7,'📋 Nov 2026'!$C$5:$C$60,"<"&$D7)+COUNTIFS('📋 Dec 2026'!$B$5:$B$60,$A7,'📋 Dec 2026'!$C$5:$C$60,"<"&$D7))+(COUNTIFS('📋 May 2026'!$B$5:$B$60,$A7,'📋 May 2026'!$AB$5:$AB$60,"Alumni")+COUNTIFS('📋 Jun 2026'!$B$5:$B$60,$A7,'📋 Jun 2026'!$AB$5:$AB$60,"Alumni")+COUNTIFS('📋 Jul 2026'!$B$5:$B$60,$A7,'📋 Jul 2026'!$AB$5:$AB$60,"Alumni")+COUNTIFS('📋 Aug 2026'!$B$5:$B$60,$A7,'📋 Aug 2026'!$AB$5:$AB$60,"Alumni")+COUNTIFS('📋 Sep 2026'!$B$5:$B$60,$A7,'📋 Sep 2026'!$AB$5:$AB$60,"Alumni")+COUNTIFS('📋 Oct 2026'!$B$5:$B$60,$A7,'📋 Oct 2026'!$AB$5:$AB$60,"Alumni")+COUNTIFS('📋 Nov 2026'!$B$5:$B$60,$A7,'📋 Nov 2026'!$AB$5:$AB$60,"Alumni")+COUNTIFS('📋 Dec 2026'!$B$5:$B$60,$A7,'📋 Dec 2026'!$AB$5:$AB$60,"Alumni"))>=1,"Alumni","New")) -> New
A8: Pedro Mendoza | B8: M1-B | C8: Occupied | D8: 46176 | E8: DTX/RTC | F8: DTX/RTC | G8: 30 | H8: Blue Shield CA | I8: Readmit | J8: Matthew | K8: N | N8: 46205 | O8: =IF($A8="","",IF($N8<>"",$N8,IF(AND($D8<>"",$G8<>""),$D8+$G8,""))) -> 46205 | P8: =IF(O8="","",O8-TODAY()) -> 15 | Q8: =IF(OR($A8="",$D8=""),"",IF((COUNTIFS('📋 May 2026'!$B$5:$B$60,$A8,'📋 May 2026'!$C$5:$C$60,"<"&$D8)+COUNTIFS('📋 Jun 2026'!$B$5:$B$60,$A8,'📋 Jun 2026'!$C$5:$C$60,"<"&$D8)+COUNTIFS('📋 Jul 2026'!$B$5:$B$60,$A8,'📋 Jul 2026'!$C$5:$C$60,"<"&$D8)+COUNTIFS('📋 Aug 2026'!$B$5:$B$60,$A8,'📋 Aug 2026'!$C$5:$C$60,"<"&$D8)+COUNTIFS('📋 Sep 2026'!$B$5:$B$60,$A8,'📋 Sep 2026'!$C$5:$C$60,"<"&$D8)+COUNTIFS('📋 Oct 2026'!$B$5:$B$60,$A8,'📋 Oct 2026'!$C$5:$C$60,"<"&$D8)+COUNTIFS('📋 Nov 2026'!$B$5:$B$60,$A8,'📋 Nov 2026'!$C$5:$C$60,"<"&$D8)+COUNTIFS('📋 Dec 2026'!$B$5:$B$60,$A8,'📋 Dec 2026'!$C$5:$C$60,"<"&$D8))+(COUNTIFS('📋 May 2026'!$B$5:$B$60,$A8,'📋 May 2026'!$AB$5:$AB$60,"Alumni")+COUNTIFS('📋 Jun 2026'!$B$5:$B$60,$A8,'📋 Jun 2026'!$AB$5:$AB$60,"Alumni")+COUNTIFS('📋 Jul 2026'!$B$5:$B$60,$A8,'📋 Jul 2026'!$AB$5:$AB$60,"Alumni")+COUNTIFS('📋 Aug 2026'!$B$5:$B$60,$A8,'📋 Aug 2026'!$AB$5:$AB$60,"Alumni")+COUNTIFS('📋 Sep 2026'!$B$5:$B$60,$A8,'📋 Sep 2026'!$AB$5:$AB$60,"Alumni")+COUNTIFS('📋 Oct 2026'!$B$5:$B$60,$A8,'📋 Oct 2026'!$AB$5:$AB$60,"Alumni")+COUNTIFS('📋 Nov 2026'!$B$5:$B$60,$A8,'📋 Nov 2026'!$AB$5:$AB$60,"Alumni")+COUNTIFS('📋 Dec 2026'!$B$5:$B$60,$A8,'📋 Dec 2026'!$AB$5:$AB$60,"Alumni"))>=1,"Alumni","New")) -> Alumni
B9: M2-A | O9: =IF($A9="","",IF($N9<>"",$N9,IF(AND($D9<>"",$G9<>""),$D9+$G9,""))) | P9: =IF(O9="","",O9-TODAY()) | Q9: =IF(OR($A9="",$D9=""),"",IF((COUNTIFS('📋 May 2026'!$B$5:$B$60,$A9,'📋 May 2026'!$C$5:$C$60,"<"&$D9)+COUNTIFS('📋 Jun 2026'!$B$5:$B$60,$A9,'📋 Jun 2026'!$C$5:$C$60,"<"&$D9)+COUNTIFS('📋 Jul 2026'!$B$5:$B$60,$A9,'📋 Jul 2026'!$C$5:$C$60,"<"&$D9)+COUNTIFS('📋 Aug 2026'!$B$5:$B$60,$A9,'📋 Aug 2026'!$C$5:$C$60,"<"&$D9)+COUNTIFS('📋 Sep 2026'!$B$5:$B$60,$A9,'📋 Sep 2026'!$C$5:$C$60,"<"&$D9)+COUNTIFS('📋 Oct 2026'!$B$5:$B$60,$A9,'📋 Oct 2026'!$C$5:$C$60,"<"&$D9)+COUNTIFS('📋 Nov 2026'!$B$5:$B$60,$A9,'📋 Nov 2026'!$C$5:$C$60,"<"&$D9)+COUNTIFS('📋 Dec 2026'!$B$5:$B$60,$A9,'📋 Dec 2026'!$C$5:$C$60,"<"&$D9))+(COUNTIFS('📋 May 2026'!$B$5:$B$60,$A9,'📋 May 2026'!$AB$5:$AB$60,"Alumni")+COUNTIFS('📋 Jun 2026'!$B$5:$B$60,$A9,'📋 Jun 2026'!$AB$5:$AB$60,"Alumni")+COUNTIFS('📋 Jul 2026'!$B$5:$B$60,$A9,'📋 Jul 2026'!$AB$5:$AB$60,"Alumni")+COUNTIFS('📋 Aug 2026'!$B$5:$B$60,$A9,'📋 Aug 2026'!$AB$5:$AB$60,"Alumni")+COUNTIFS('📋 Sep 2026'!$B$5:$B$60,$A9,'📋 Sep 2026'!$AB$5:$AB$60,"Alumni")+COUNTIFS('📋 Oct 2026'!$B$5:$B$60,$A9,'📋 Oct 2026'!$AB$5:$AB$60,"Alumni")+COUNTIFS('📋 Nov 2026'!$B$5:$B$60,$A9,'📋 Nov 2026'!$AB$5:$AB$60,"Alumni")+COUNTIFS('📋 Dec 2026'!$B$5:$B$60,$A9,'📋 Dec 2026'!$AB$5:$AB$60,"Alumni"))>=1,"Alumni","New"))
A10: Darian Loehner | B10: M2-B | C10: Occupied | D10: 46183 | E10: DTX | F10: DTX | G10: 10 | H10: Aetna | I10: Readmit | J10: Amy | K10: Y | O10: =IF($A10="","",IF($N10<>"",$N10,IF(AND($D10<>"",$G10<>""),$D10+$G10,""))) -> 46193 | P10: =IF(O10="","",O10-TODAY()) -> 3 | Q10: =IF(OR($A10="",$D10=""),"",IF((COUNTIFS('📋 May 2026'!$B$5:$B$60,$A10,'📋 May 2026'!$C$5:$C$60,"<"&$D10)+COUNTIFS('📋 Jun 2026'!$B$5:$B$60,$A10,'📋 Jun 2026'!$C$5:$C$60,"<"&$D10)+COUNTIFS('📋 Jul 2026'!$B$5:$B$60,$A10,'📋 Jul 2026'!$C$5:$C$60,"<"&$D10)+COUNTIFS('📋 Aug 2026'!$B$5:$B$60,$A10,'📋 Aug 2026'!$C$5:$C$60,"<"&$D10)+COUNTIFS('📋 Sep 2026'!$B$5:$B$60,$A10,'📋 Sep 2026'!$C$5:$C$60,"<"&$D10)+COUNTIFS('📋 Oct 2026'!$B$5:$B$60,$A10,'📋 Oct 2026'!$C$5:$C$60,"<"&$D10)+COUNTIFS('📋 Nov 2026'!$B$5:$B$60,$A10,'📋 Nov 2026'!$C$5:$C$60,"<"&$D10)+COUNTIFS('📋 Dec 2026'!$B$5:$B$60,$A10,'📋 Dec 2026'!$C$5:$C$60,"<"&$D10))+(COUNTIFS('📋 May 2026'!$B$5:$B$60,$A10,'📋 May 2026'!$AB$5:$AB$60,"Alumni")+COUNTIFS('📋 Jun 2026'!$B$5:$B$60,$A10,'📋 Jun 2026'!$AB$5:$AB$60,"Alumni")+COUNTIFS('📋 Jul 2026'!$B$5:$B$60,$A10,'📋 Jul 2026'!$AB$5:$AB$60,"Alumni")+COUNTIFS('📋 Aug 2026'!$B$5:$B$60,$A10,'📋 Aug 2026'!$AB$5:$AB$60,"Alumni")+COUNTIFS('📋 Sep 2026'!$B$5:$B$60,$A10,'📋 Sep 2026'!$AB$5:$AB$60,"Alumni")+COUNTIFS('📋 Oct 2026'!$B$5:$B$60,$A10,'📋 Oct 2026'!$AB$5:$AB$60,"Alumni")+COUNTIFS('📋 Nov 2026'!$B$5:$B$60,$A10,'📋 Nov 2026'!$AB$5:$AB$60,"Alumni")+COUNTIFS('📋 Dec 2026'!$B$5:$B$60,$A10,'📋 Dec 2026'!$AB$5:$AB$60,"Alumni"))>=1,"Alumni","New")) -> Alumni
A11: Jill Labate | B11: M3-A | C11: Occupied | D11: 46187 | E11: DTX/RTC | F11: DTX/RTC | G11: 21 | H11: Cigna/Evernorth | I11: Readmit/Rise | J11: Matthew | O11: =IF($A11="","",IF($N11<>"",$N11,IF(AND($D11<>"",$G11<>""),$D11+$G11,""))) -> 46208 | P11: =IF(O11="","",O11-TODAY()) -> 18 | Q11: =IF(OR($A11="",$D11=""),"",IF((COUNTIFS('📋 May 2026'!$B$5:$B$60,$A11,'📋 May 2026'!$C$5:$C$60,"<"&$D11)+COUNTIFS('📋 Jun 2026'!$B$5:$B$60,$A11,'📋 Jun 2026'!$C$5:$C$60,"<"&$D11)+COUNTIFS('📋 Jul 2026'!$B$5:$B$60,$A11,'📋 Jul 2026'!$C$5:$C$60,"<"&$D11)+COUNTIFS('📋 Aug 2026'!$B$5:$B$60,$A11,'📋 Aug 2026'!$C$5:$C$60,"<"&$D11)+COUNTIFS('📋 Sep 2026'!$B$5:$B$60,$A11,'📋 Sep 2026'!$C$5:$C$60,"<"&$D11)+COUNTIFS('📋 Oct 2026'!$B$5:$B$60,$A11,'📋 Oct 2026'!$C$5:$C$60,"<"&$D11)+COUNTIFS('📋 Nov 2026'!$B$5:$B$60,$A11,'📋 Nov 2026'!$C$5:$C$60,"<"&$D11)+COUNTIFS('📋 Dec 2026'!$B$5:$B$60,$A11,'📋 Dec 2026'!$C$5:$C$60,"<"&$D11))+(COUNTIFS('📋 May 2026'!$B$5:$B$60,$A11,'📋 May 2026'!$AB$5:$AB$60,"Alumni")+COUNTIFS('📋 Jun 2026'!$B$5:$B$60,$A11,'📋 Jun 2026'!$AB$5:$AB$60,"Alumni")+COUNTIFS('📋 Jul 2026'!$B$5:$B$60,$A11,'📋 Jul 2026'!$AB$5:$AB$60,"Alumni")+COUNTIFS('📋 Aug 2026'!$B$5:$B$60,$A11,'📋 Aug 2026'!$AB$5:$AB$60,"Alumni")+COUNTIFS('📋 Sep 2026'!$B$5:$B$60,$A11,'📋 Sep 2026'!$AB$5:$AB$60,"Alumni")+COUNTIFS('📋 Oct 2026'!$B$5:$B$60,$A11,'📋 Oct 2026'!$AB$5:$AB$60,"Alumni")+COUNTIFS('📋 Nov 2026'!$B$5:$B$60,$A11,'📋 Nov 2026'!$AB$5:$AB$60,"Alumni")+COUNTIFS('📋 Dec 2026'!$B$5:$B$60,$A11,'📋 Dec 2026'!$AB$5:$AB$60,"Alumni"))>=1,"Alumni","New")) -> Alumni
A12: Monica Gamboa | B12: M3-B | C12: Occupied | D12: 46184 | E12: DTX/RTC | F12: DTX/RTC | G12: 10 | H12: Molina CA | I12: Readmit | J12: Amy | K12: N | N12: 46194 | O12: =IF($A12="","",IF($N12<>"",$N12,IF(AND($D12<>"",$G12<>""),$D12+$G12,""))) -> 46194 | P12: =IF(O12="","",O12-TODAY()) -> 4 | Q12: =IF(OR($A12="",$D12=""),"",IF((COUNTIFS('📋 May 2026'!$B$5:$B$60,$A12,'📋 May 2026'!$C$5:$C$60,"<"&$D12)+COUNTIFS('📋 Jun 2026'!$B$5:$B$60,$A12,'📋 Jun 2026'!$C$5:$C$60,"<"&$D12)+COUNTIFS('📋 Jul 2026'!$B$5:$B$60,$A12,'📋 Jul 2026'!$C$5:$C$60,"<"&$D12)+COUNTIFS('📋 Aug 2026'!$B$5:$B$60,$A12,'📋 Aug 2026'!$C$5:$C$60,"<"&$D12)+COUNTIFS('📋 Sep 2026'!$B$5:$B$60,$A12,'📋 Sep 2026'!$C$5:$C$60,"<"&$D12)+COUNTIFS('📋 Oct 2026'!$B$5:$B$60,$A12,'📋 Oct 2026'!$C$5:$C$60,"<"&$D12)+COUNTIFS('📋 Nov 2026'!$B$5:$B$60,$A12,'📋 Nov 2026'!$C$5:$C$60,"<"&$D12)+COUNTIFS('📋 Dec 2026'!$B$5:$B$60,$A12,'📋 Dec 2026'!$C$5:$C$60,"<"&$D12))+(COUNTIFS('📋 May 2026'!$B$5:$B$60,$A12,'📋 May 2026'!$AB$5:$AB$60,"Alumni")+COUNTIFS('📋 Jun 2026'!$B$5:$B$60,$A12,'📋 Jun 2026'!$AB$5:$AB$60,"Alumni")+COUNTIFS('📋 Jul 2026'!$B$5:$B$60,$A12,'📋 Jul 2026'!$AB$5:$AB$60,"Alumni")+COUNTIFS('📋 Aug 2026'!$B$5:$B$60,$A12,'📋 Aug 2026'!$AB$5:$AB$60,"Alumni")+COUNTIFS('📋 Sep 2026'!$B$5:$B$60,$A12,'📋 Sep 2026'!$AB$5:$AB$60,"Alumni")+COUNTIFS('📋 Oct 2026'!$B$5:$B$60,$A12,'📋 Oct 2026'!$AB$5:$AB$60,"Alumni")+COUNTIFS('📋 Nov 2026'!$B$5:$B$60,$A12,'📋 Nov 2026'!$AB$5:$AB$60,"Alumni")+COUNTIFS('📋 Dec 2026'!$B$5:$B$60,$A12,'📋 Dec 2026'!$AB$5:$AB$60,"Alumni"))>=1,"Alumni","New")) -> Alumni
A13: Bradey Bauer | B13: B1-A | C13: Occupied | D13: 46186 | E13: DTX/RTC | F13: DTX/RTC | G13: 30 | H13: Anthem BC | O13: =IF($A13="","",IF($N13<>"",$N13,IF(AND($D13<>"",$G13<>""),$D13+$G13,""))) -> 46216 | P13: =IF(O13="","",O13-TODAY()) -> 26 | Q13: =IF(OR($A13="",$D13=""),"",IF((COUNTIFS('📋 May 2026'!$B$5:$B$60,$A13,'📋 May 2026'!$C$5:$C$60,"<"&$D13)+COUNTIFS('📋 Jun 2026'!$B$5:$B$60,$A13,'📋 Jun 2026'!$C$5:$C$60,"<"&$D13)+COUNTIFS('📋 Jul 2026'!$B$5:$B$60,$A13,'📋 Jul 2026'!$C$5:$C$60,"<"&$D13)+COUNTIFS('📋 Aug 2026'!$B$5:$B$60,$A13,'📋 Aug 2026'!$C$5:$C$60,"<"&$D13)+COUNTIFS('📋 Sep 2026'!$B$5:$B$60,$A13,'📋 Sep 2026'!$C$5:$C$60,"<"&$D13)+COUNTIFS('📋 Oct 2026'!$B$5:$B$60,$A13,'📋 Oct 2026'!$C$5:$C$60,"<"&$D13)+COUNTIFS('📋 Nov 2026'!$B$5:$B$60,$A13,'📋 Nov 2026'!$C$5:$C$60,"<"&$D13)+COUNTIFS('📋 Dec 2026'!$B$5:$B$60,$A13,'📋 Dec 2026'!$C$5:$C$60,"<"&$D13))+(COUNTIFS('📋 May 2026'!$B$5:$B$60,$A13,'📋 May 2026'!$AB$5:$AB$60,"Alumni")+COUNTIFS('📋 Jun 2026'!$B$5:$B$60,$A13,'📋 Jun 2026'!$AB$5:$AB$60,"Alumni")+COUNTIFS('📋 Jul 2026'!$B$5:$B$60,$A13,'📋 Jul 2026'!$AB$5:$AB$60,"Alumni")+COUNTIFS('📋 Aug 2026'!$B$5:$B$60,$A13,'📋 Aug 2026'!$AB$5:$AB$60,"Alumni")+COUNTIFS('📋 Sep 2026'!$B$5:$B$60,$A13,'📋 Sep 2026'!$AB$5:$AB$60,"Alumni")+COUNTIFS('📋 Oct 2026'!$B$5:$B$60,$A13,'📋 Oct 2026'!$AB$5:$AB$60,"Alumni")+COUNTIFS('📋 Nov 2026'!$B$5:$B$60,$A13,'📋 Nov 2026'!$AB$5:$AB$60,"Alumni")+COUNTIFS('📋 Dec 2026'!$B$5:$B$60,$A13,'📋 Dec 2026'!$AB$5:$AB$60,"Alumni"))>=1,"Alumni","New")) -> Alumni
A14: Garrett Johnson | B14: B1-B | C14: Occupied | D14: 46186 | E14: RTC | F14: RTC | G14: 30 | H14: UHC | I14: web | J14: Nelson | K14: Y | O14: =IF($A14="","",IF($N14<>"",$N14,IF(AND($D14<>"",$G14<>""),$D14+$G14,""))) -> 46216 | P14: =IF(O14="","",O14-TODAY()) -> 26 | Q14: =IF(OR($A14="",$D14=""),"",IF((COUNTIFS('📋 May 2026'!$B$5:$B$60,$A14,'📋 May 2026'!$C$5:$C$60,"<"&$D14)+COUNTIFS('📋 Jun 2026'!$B$5:$B$60,$A14,'📋 Jun 2026'!$C$5:$C$60,"<"&$D14)+COUNTIFS('📋 Jul 2026'!$B$5:$B$60,$A14,'📋 Jul 2026'!$C$5:$C$60,"<"&$D14)+COUNTIFS('📋 Aug 2026'!$B$5:$B$60,$A14,'📋 Aug 2026'!$C$5:$C$60,"<"&$D14)+COUNTIFS('📋 Sep 2026'!$B$5:$B$60,$A14,'📋 Sep 2026'!$C$5:$C$60,"<"&$D14)+COUNTIFS('📋 Oct 2026'!$B$5:$B$60,$A14,'📋 Oct 2026'!$C$5:$C$60,"<"&$D14)+COUNTIFS('📋 Nov 2026'!$B$5:$B$60,$A14,'📋 Nov 2026'!$C$5:$C$60,"<"&$D14)+COUNTIFS('📋 Dec 2026'!$B$5:$B$60,$A14,'📋 Dec 2026'!$C$5:$C$60,"<"&$D14))+(COUNTIFS('📋 May 2026'!$B$5:$B$60,$A14,'📋 May 2026'!$AB$5:$AB$60,"Alumni")+COUNTIFS('📋 Jun 2026'!$B$5:$B$60,$A14,'📋 Jun 2026'!$AB$5:$AB$60,"Alumni")+COUNTIFS('📋 Jul 2026'!$B$5:$B$60,$A14,'📋 Jul 2026'!$AB$5:$AB$60,"Alumni")+COUNTIFS('📋 Aug 2026'!$B$5:$B$60,$A14,'📋 Aug 2026'!$AB$5:$AB$60,"Alumni")+COUNTIFS('📋 Sep 2026'!$B$5:$B$60,$A14,'📋 Sep 2026'!$AB$5:$AB$60,"Alumni")+COUNTIFS('📋 Oct 2026'!$B$5:$B$60,$A14,'📋 Oct 2026'!$AB$5:$AB$60,"Alumni")+COUNTIFS('📋 Nov 2026'!$B$5:$B$60,$A14,'📋 Nov 2026'!$AB$5:$AB$60,"Alumni")+COUNTIFS('📋 Dec 2026'!$B$5:$B$60,$A14,'📋 Dec 2026'!$AB$5:$AB$60,"Alumni"))>=1,"Alumni","New")) -> New
A15: Kyle Samia | B15: B2-A | C15: Occupied | D15: 46184 | E15: DTX/RTC | F15: DTX/RTC | G15: 30 | H15: Cigna/Evernorth | I15: web | J15: Matthew | O15: =IF($A15="","",IF($N15<>"",$N15,IF(AND($D15<>"",$G15<>""),$D15+$G15,""))) -> 46214 | P15: =IF(O15="","",O15-TODAY()) -> 24 | Q15: =IF(OR($A15="",$D15=""),"",IF((COUNTIFS('📋 May 2026'!$B$5:$B$60,$A15,'📋 May 2026'!$C$5:$C$60,"<"&$D15)+COUNTIFS('📋 Jun 2026'!$B$5:$B$60,$A15,'📋 Jun 2026'!$C$5:$C$60,"<"&$D15)+COUNTIFS('📋 Jul 2026'!$B$5:$B$60,$A15,'📋 Jul 2026'!$C$5:$C$60,"<"&$D15)+COUNTIFS('📋 Aug 2026'!$B$5:$B$60,$A15,'📋 Aug 2026'!$C$5:$C$60,"<"&$D15)+COUNTIFS('📋 Sep 2026'!$B$5:$B$60,$A15,'📋 Sep 2026'!$C$5:$C$60,"<"&$D15)+COUNTIFS('📋 Oct 2026'!$B$5:$B$60,$A15,'📋 Oct 2026'!$C$5:$C$60,"<"&$D15)+COUNTIFS('📋 Nov 2026'!$B$5:$B$60,$A15,'📋 Nov 2026'!$C$5:$C$60,"<"&$D15)+COUNTIFS('📋 Dec 2026'!$B$5:$B$60,$A15,'📋 Dec 2026'!$C$5:$C$60,"<"&$D15))+(COUNTIFS('📋 May 2026'!$B$5:$B$60,$A15,'📋 May 2026'!$AB$5:$AB$60,"Alumni")+COUNTIFS('📋 Jun 2026'!$B$5:$B$60,$A15,'📋 Jun 2026'!$AB$5:$AB$60,"Alumni")+COUNTIFS('📋 Jul 2026'!$B$5:$B$60,$A15,'📋 Jul 2026'!$AB$5:$AB$60,"Alumni")+COUNTIFS('📋 Aug 2026'!$B$5:$B$60,$A15,'📋 Aug 2026'!$AB$5:$AB$60,"Alumni")+COUNTIFS('📋 Sep 2026'!$B$5:$B$60,$A15,'📋 Sep 2026'!$AB$5:$AB$60,"Alumni")+COUNTIFS('📋 Oct 2026'!$B$5:$B$60,$A15,'📋 Oct 2026'!$AB$5:$AB$60,"Alumni")+COUNTIFS('📋 Nov 2026'!$B$5:$B$60,$A15,'📋 Nov 2026'!$AB$5:$AB$60,"Alumni")+COUNTIFS('📋 Dec 2026'!$B$5:$B$60,$A15,'📋 Dec 2026'!$AB$5:$AB$60,"Alumni"))>=1,"Alumni","New")) -> New
A16: Jamal Williams | B16: B2-B | C16: Occupied | D16: 46183 | E16: DTX/RTC | F16: DTX/RTC | G16: 30 | H16: Blue Shield CA | I16: The Canyon | J16: Ahbra | O16: =IF($A16="","",IF($N16<>"",$N16,IF(AND($D16<>"",$G16<>""),$D16+$G16,""))) -> 46213 | P16: =IF(O16="","",O16-TODAY()) -> 23 | Q16: =IF(OR($A16="",$D16=""),"",IF((COUNTIFS('📋 May 2026'!$B$5:$B$60,$A16,'📋 May 2026'!$C$5:$C$60,"<"&$D16)+COUNTIFS('📋 Jun 2026'!$B$5:$B$60,$A16,'📋 Jun 2026'!$C$5:$C$60,"<"&$D16)+COUNTIFS('📋 Jul 2026'!$B$5:$B$60,$A16,'📋 Jul 2026'!$C$5:$C$60,"<"&$D16)+COUNTIFS('📋 Aug 2026'!$B$5:$B$60,$A16,'📋 Aug 2026'!$C$5:$C$60,"<"&$D16)+COUNTIFS('📋 Sep 2026'!$B$5:$B$60,$A16,'📋 Sep 2026'!$C$5:$C$60,"<"&$D16)+COUNTIFS('📋 Oct 2026'!$B$5:$B$60,$A16,'📋 Oct 2026'!$C$5:$C$60,"<"&$D16)+COUNTIFS('📋 Nov 2026'!$B$5:$B$60,$A16,'📋 Nov 2026'!$C$5:$C$60,"<"&$D16)+COUNTIFS('📋 Dec 2026'!$B$5:$B$60,$A16,'📋 Dec 2026'!$C$5:$C$60,"<"&$D16))+(COUNTIFS('📋 May 2026'!$B$5:$B$60,$A16,'📋 May 2026'!$AB$5:$AB$60,"Alumni")+COUNTIFS('📋 Jun 2026'!$B$5:$B$60,$A16,'📋 Jun 2026'!$AB$5:$AB$60,"Alumni")+COUNTIFS('📋 Jul 2026'!$B$5:$B$60,$A16,'📋 Jul 2026'!$AB$5:$AB$60,"Alumni")+COUNTIFS('📋 Aug 2026'!$B$5:$B$60,$A16,'📋 Aug 2026'!$AB$5:$AB$60,"Alumni")+COUNTIFS('📋 Sep 2026'!$B$5:$B$60,$A16,'📋 Sep 2026'!$AB$5:$AB$60,"Alumni")+COUNTIFS('📋 Oct 2026'!$B$5:$B$60,$A16,'📋 Oct 2026'!$AB$5:$AB$60,"Alumni")+COUNTIFS('📋 Nov 2026'!$B$5:$B$60,$A16,'📋 Nov 2026'!$AB$5:$AB$60,"Alumni")+COUNTIFS('📋 Dec 2026'!$B$5:$B$60,$A16,'📋 Dec 2026'!$AB$5:$AB$60,"Alumni"))>=1,"Alumni","New")) -> New
A17: Christopher Avolio | B17: B3-A | C17: Occupied | D17: 46169 | E17: DTX/RTC | F17: DTX/RTC | G17: 30 | H17: Blue Shield PPO | I17: Montare | J17: Amy | K17: N | N17: 46205 | O17: =IF($A17="","",IF($N17<>"",$N17,IF(AND($D17<>"",$G17<>""),$D17+$G17,""))) -> 46205 | P17: =IF(O17="","",O17-TODAY()) -> 15 | Q17: =IF(OR($A17="",$D17=""),"",IF((COUNTIFS('📋 May 2026'!$B$5:$B$60,$A17,'📋 May 2026'!$C$5:$C$60,"<"&$D17)+COUNTIFS('📋 Jun 2026'!$B$5:$B$60,$A17,'📋 Jun 2026'!$C$5:$C$60,"<"&$D17)+COUNTIFS('📋 Jul 2026'!$B$5:$B$60,$A17,'📋 Jul 2026'!$C$5:$C$60,"<"&$D17)+COUNTIFS('📋 Aug 2026'!$B$5:$B$60,$A17,'📋 Aug 2026'!$C$5:$C$60,"<"&$D17)+COUNTIFS('📋 Sep 2026'!$B$5:$B$60,$A17,'📋 Sep 2026'!$C$5:$C$60,"<"&$D17)+COUNTIFS('📋 Oct 2026'!$B$5:$B$60,$A17,'📋 Oct 2026'!$C$5:$C$60,"<"&$D17)+COUNTIFS('📋 Nov 2026'!$B$5:$B$60,$A17,'📋 Nov 2026'!$C$5:$C$60,"<"&$D17)+COUNTIFS('📋 Dec 2026'!$B$5:$B$60,$A17,'📋 Dec 2026'!$C$5:$C$60,"<"&$D17))+(COUNTIFS('📋 May 2026'!$B$5:$B$60,$A17,'📋 May 2026'!$AB$5:$AB$60,"Alumni")+COUNTIFS('📋 Jun 2026'!$B$5:$B$60,$A17,'📋 Jun 2026'!$AB$5:$AB$60,"Alumni")+COUNTIFS('📋 Jul 2026'!$B$5:$B$60,$A17,'📋 Jul 2026'!$AB$5:$AB$60,"Alumni")+COUNTIFS('📋 Aug 2026'!$B$5:$B$60,$A17,'📋 Aug 2026'!$AB$5:$AB$60,"Alumni")+COUNTIFS('📋 Sep 2026'!$B$5:$B$60,$A17,'📋 Sep 2026'!$AB$5:$AB$60,"Alumni")+COUNTIFS('📋 Oct 2026'!$B$5:$B$60,$A17,'📋 Oct 2026'!$AB$5:$AB$60,"Alumni")+COUNTIFS('📋 Nov 2026'!$B$5:$B$60,$A17,'📋 Nov 2026'!$AB$5:$AB$60,"Alumni")+COUNTIFS('📋 Dec 2026'!$B$5:$B$60,$A17,'📋 Dec 2026'!$AB$5:$AB$60,"Alumni"))>=1,"Alumni","New")) -> New
A18: Jason Schnell | B18: B3-B | C18: Occupied | D18: 46164 | E18: DTX/RTC | F18: DTX/RTC | G18: 30 | H18: Blue Shield CA | I18: Readmit | J18: Amy | K18: N | N18: 46203 | O18: =IF($A18="","",IF($N18<>"",$N18,IF(AND($D18<>"",$G18<>""),$D18+$G18,""))) -> 46203 | P18: =IF(O18="","",O18-TODAY()) -> 13 | Q18: =IF(OR($A18="",$D18=""),"",IF((COUNTIFS('📋 May 2026'!$B$5:$B$60,$A18,'📋 May 2026'!$C$5:$C$60,"<"&$D18)+COUNTIFS('📋 Jun 2026'!$B$5:$B$60,$A18,'📋 Jun 2026'!$C$5:$C$60,"<"&$D18)+COUNTIFS('📋 Jul 2026'!$B$5:$B$60,$A18,'📋 Jul 2026'!$C$5:$C$60,"<"&$D18)+COUNTIFS('📋 Aug 2026'!$B$5:$B$60,$A18,'📋 Aug 2026'!$C$5:$C$60,"<"&$D18)+COUNTIFS('📋 Sep 2026'!$B$5:$B$60,$A18,'📋 Sep 2026'!$C$5:$C$60,"<"&$D18)+COUNTIFS('📋 Oct 2026'!$B$5:$B$60,$A18,'📋 Oct 2026'!$C$5:$C$60,"<"&$D18)+COUNTIFS('📋 Nov 2026'!$B$5:$B$60,$A18,'📋 Nov 2026'!$C$5:$C$60,"<"&$D18)+COUNTIFS('📋 Dec 2026'!$B$5:$B$60,$A18,'📋 Dec 2026'!$C$5:$C$60,"<"&$D18))+(COUNTIFS('📋 May 2026'!$B$5:$B$60,$A18,'📋 May 2026'!$AB$5:$AB$60,"Alumni")+COUNTIFS('📋 Jun 2026'!$B$5:$B$60,$A18,'📋 Jun 2026'!$AB$5:$AB$60,"Alumni")+COUNTIFS('📋 Jul 2026'!$B$5:$B$60,$A18,'📋 Jul 2026'!$AB$5:$AB$60,"Alumni")+COUNTIFS('📋 Aug 2026'!$B$5:$B$60,$A18,'📋 Aug 2026'!$AB$5:$AB$60,"Alumni")+COUNTIFS('📋 Sep 2026'!$B$5:$B$60,$A18,'📋 Sep 2026'!$AB$5:$AB$60,"Alumni")+COUNTIFS('📋 Oct 2026'!$B$5:$B$60,$A18,'📋 Oct 2026'!$AB$5:$AB$60,"Alumni")+COUNTIFS('📋 Nov 2026'!$B$5:$B$60,$A18,'📋 Nov 2026'!$AB$5:$AB$60,"Alumni")+COUNTIFS('📋 Dec 2026'!$B$5:$B$60,$A18,'📋 Dec 2026'!$AB$5:$AB$60,"Alumni"))>=1,"Alumni","New")) -> Alumni
A20: 🏢 HPE — BURBANK · HOUSE 1 (22913)
A21: Allisa Leuvrey | B21: H1-1A | C21: Occupied | D21: 46185 | E21: DTX | F21: DTX | G21: 7 | H21: Blue Shield CA | I21: web | J21: Amy | K21: N | O21: =IF($A21="","",IF($N21<>"",$N21,IF(AND($D21<>"",$G21<>""),$D21+$G21,""))) -> 46192 | P21: =IF(O21="","",O21-TODAY()) -> 2 | Q21: =IF(OR($A21="",$D21=""),"",IF((COUNTIFS('📋 May 2026'!$B$5:$B$60,$A21,'📋 May 2026'!$C$5:$C$60,"<"&$D21)+COUNTIFS('📋 Jun 2026'!$B$5:$B$60,$A21,'📋 Jun 2026'!$C$5:$C$60,"<"&$D21)+COUNTIFS('📋 Jul 2026'!$B$5:$B$60,$A21,'📋 Jul 2026'!$C$5:$C$60,"<"&$D21)+COUNTIFS('📋 Aug 2026'!$B$5:$B$60,$A21,'📋 Aug 2026'!$C$5:$C$60,"<"&$D21)+COUNTIFS('📋 Sep 2026'!$B$5:$B$60,$A21,'📋 Sep 2026'!$C$5:$C$60,"<"&$D21)+COUNTIFS('📋 Oct 2026'!$B$5:$B$60,$A21,'📋 Oct 2026'!$C$5:$C$60,"<"&$D21)+COUNTIFS('📋 Nov 2026'!$B$5:$B$60,$A21,'📋 Nov 2026'!$C$5:$C$60,"<"&$D21)+COUNTIFS('📋 Dec 2026'!$B$5:$B$60,$A21,'📋 Dec 2026'!$C$5:$C$60,"<"&$D21))+(COUNTIFS('📋 May 2026'!$B$5:$B$60,$A21,'📋 May 2026'!$AB$5:$AB$60,"Alumni")+COUNTIFS('📋 Jun 2026'!$B$5:$B$60,$A21,'📋 Jun 2026'!$AB$5:$AB$60,"Alumni")+COUNTIFS('📋 Jul 2026'!$B$5:$B$60,$A21,'📋 Jul 2026'!$AB$5:$AB$60,"Alumni")+COUNTIFS('📋 Aug 2026'!$B$5:$B$60,$A21,'📋 Aug 2026'!$AB$5:$AB$60,"Alumni")+COUNTIFS('📋 Sep 2026'!$B$5:$B$60,$A21,'📋 Sep 2026'!$AB$5:$AB$60,"Alumni")+COUNTIFS('📋 Oct 2026'!$B$5:$B$60,$A21,'📋 Oct 2026'!$AB$5:$AB$60,"Alumni")+COUNTIFS('📋 Nov 2026'!$B$5:$B$60,$A21,'📋 Nov 2026'!$AB$5:$AB$60,"Alumni")+COUNTIFS('📋 Dec 2026'!$B$5:$B$60,$A21,'📋 Dec 2026'!$AB$5:$AB$60,"Alumni"))>=1,"Alumni","New")) -> New
A22: Cree Lamere | B22: H1-1B | C22: Occupied | D22: 46170 | E22: DTX/RTC | F22: DTX/RTC | G22: 30 | H22: Blue Shield CA | I22: Ahbra/Profound | J22: Amy | K22: N | N22: 46202 | O22: =IF($A22="","",IF($N22<>"",$N22,IF(AND($D22<>"",$G22<>""),$D22+$G22,""))) -> 46202 | P22: =IF(O22="","",O22-TODAY()) -> 12 | Q22: =IF(OR($A22="",$D22=""),"",IF((COUNTIFS('📋 May 2026'!$B$5:$B$60,$A22,'📋 May 2026'!$C$5:$C$60,"<"&$D22)+COUNTIFS('📋 Jun 2026'!$B$5:$B$60,$A22,'📋 Jun 2026'!$C$5:$C$60,"<"&$D22)+COUNTIFS('📋 Jul 2026'!$B$5:$B$60,$A22,'📋 Jul 2026'!$C$5:$C$60,"<"&$D22)+COUNTIFS('📋 Aug 2026'!$B$5:$B$60,$A22,'📋 Aug 2026'!$C$5:$C$60,"<"&$D22)+COUNTIFS('📋 Sep 2026'!$B$5:$B$60,$A22,'📋 Sep 2026'!$C$5:$C$60,"<"&$D22)+COUNTIFS('📋 Oct 2026'!$B$5:$B$60,$A22,'📋 Oct 2026'!$C$5:$C$60,"<"&$D22)+COUNTIFS('📋 Nov 2026'!$B$5:$B$60,$A22,'📋 Nov 2026'!$C$5:$C$60,"<"&$D22)+COUNTIFS('📋 Dec 2026'!$B$5:$B$60,$A22,'📋 Dec 2026'!$C$5:$C$60,"<"&$D22))+(COUNTIFS('📋 May 2026'!$B$5:$B$60,$A22,'📋 May 2026'!$AB$5:$AB$60,"Alumni")+COUNTIFS('📋 Jun 2026'!$B$5:$B$60,$A22,'📋 Jun 2026'!$AB$5:$AB$60,"Alumni")+COUNTIFS('📋 Jul 2026'!$B$5:$B$60,$A22,'📋 Jul 2026'!$AB$5:$AB$60,"Alumni")+COUNTIFS('📋 Aug 2026'!$B$5:$B$60,$A22,'📋 Aug 2026'!$AB$5:$AB$60,"Alumni")+COUNTIFS('📋 Sep 2026'!$B$5:$B$60,$A22,'📋 Sep 2026'!$AB$5:$AB$60,"Alumni")+COUNTIFS('📋 Oct 2026'!$B$5:$B$60,$A22,'📋 Oct 2026'!$AB$5:$AB$60,"Alumni")+COUNTIFS('📋 Nov 2026'!$B$5:$B$60,$A22,'📋 Nov 2026'!$AB$5:$AB$60,"Alumni")+COUNTIFS('📋 Dec 2026'!$B$5:$B$60,$A22,'📋 Dec 2026'!$AB$5:$AB$60,"Alumni"))>=1,"Alumni","New")) -> New
